<<< PROJECT PART I
<<< -- process set (n=20) with 12 CPU-bound processes
<<< -- seed=128; lambda=0.010000; bound=4096
CPU-bound process A0: arrival time 45ms; 30 CPU bursts
CPU-bound process A1: arrival time 47ms; 12 CPU bursts
CPU-bound process A2: arrival time 92ms; 30 CPU bursts
CPU-bound process A3: arrival time 324ms; 26 CPU bursts
CPU-bound process A4: arrival time 157ms; 4 CPU bursts
CPU-bound process A5: arrival time 130ms; 5 CPU bursts
CPU-bound process A6: arrival time 29ms; 18 CPU bursts
CPU-bound process A7: arrival time 54ms; 19 CPU bursts
CPU-bound process A8: arrival time 62ms; 8 CPU bursts
CPU-bound process A9: arrival time 41ms; 32 CPU bursts
CPU-bound process B0: arrival time 45ms; 19 CPU bursts
CPU-bound process B1: arrival time 9ms; 17 CPU bursts
I/O-bound process B2: arrival time 46ms; 15 CPU bursts
I/O-bound process B3: arrival time 271ms; 22 CPU bursts
I/O-bound process B4: arrival time 2ms; 16 CPU bursts
I/O-bound process B5: arrival time 140ms; 30 CPU bursts
I/O-bound process B6: arrival time 102ms; 5 CPU bursts
I/O-bound process B7: arrival time 30ms; 26 CPU bursts
I/O-bound process B8: arrival time 225ms; 20 CPU bursts
I/O-bound process B9: arrival time 95ms; 11 CPU bursts

<<< PROJECT PART II
<<< -- t_cs=4ms; alpha=0.96; t_slice=64ms
time 0ms: Simulator started for FCFS [Q empty]
time 2ms: Process B4 arrived; added to ready queue [Q B4]
time 4ms: Process B4 started using the CPU for 8ms burst [Q empty]
time 9ms: Process B1 arrived; added to ready queue [Q B1]
time 12ms: Process B4 completed a CPU burst; 15 bursts to go [Q B1]
time 12ms: Process B4 switching out of CPU; blocking on I/O until time 982ms [Q B1]
time 16ms: Process B1 started using the CPU for 28ms burst [Q empty]
time 29ms: Process A6 arrived; added to ready queue [Q A6]
time 30ms: Process B7 arrived; added to ready queue [Q A6 B7]
time 41ms: Process A9 arrived; added to ready queue [Q A6 B7 A9]
time 44ms: Process B1 completed a CPU burst; 16 bursts to go [Q A6 B7 A9]
time 44ms: Process B1 switching out of CPU; blocking on I/O until time 264ms [Q A6 B7 A9]
time 45ms: Process A0 arrived; added to ready queue [Q A6 B7 A9 A0]
time 45ms: Process B0 arrived; added to ready queue [Q A6 B7 A9 A0 B0]
time 46ms: Process B2 arrived; added to ready queue [Q A6 B7 A9 A0 B0 B2]
time 47ms: Process A1 arrived; added to ready queue [Q B7 A9 A0 B0 B2 A1]
time 48ms: Process A6 started using the CPU for 280ms burst [Q B7 A9 A0 B0 B2 A1]
time 54ms: Process A7 arrived; added to ready queue [Q B7 A9 A0 B0 B2 A1 A7]
time 62ms: Process A8 arrived; added to ready queue [Q B7 A9 A0 B0 B2 A1 A7 A8]
time 92ms: Process A2 arrived; added to ready queue [Q B7 A9 A0 B0 B2 A1 A7 A8 A2]
time 95ms: Process B9 arrived; added to ready queue [Q B7 A9 A0 B0 B2 A1 A7 A8 A2 B9]
time 102ms: Process B6 arrived; added to ready queue [Q B7 A9 A0 B0 B2 A1 A7 A8 A2 B9 B6]
time 130ms: Process A5 arrived; added to ready queue [Q B7 A9 A0 B0 B2 A1 A7 A8 A2 B9 B6 A5]
time 140ms: Process B5 arrived; added to ready queue [Q B7 A9 A0 B0 B2 A1 A7 A8 A2 B9 B6 A5 B5]
time 157ms: Process A4 arrived; added to ready queue [Q B7 A9 A0 B0 B2 A1 A7 A8 A2 B9 B6 A5 B5 A4]
time 225ms: Process B8 arrived; added to ready queue [Q B7 A9 A0 B0 B2 A1 A7 A8 A2 B9 B6 A5 B5 A4 B8]
time 264ms: Process B1 completed I/O; added to ready queue [Q B7 A9 A0 B0 B2 A1 A7 A8 A2 B9 B6 A5 B5 A4 B8 B1]
time 271ms: Process B3 arrived; added to ready queue [Q B7 A9 A0 B0 B2 A1 A7 A8 A2 B9 B6 A5 B5 A4 B8 B1 B3]
time 324ms: Process A3 arrived; added to ready queue [Q B7 A9 A0 B0 B2 A1 A7 A8 A2 B9 B6 A5 B5 A4 B8 B1 B3 A3]
time 328ms: Process A6 completed a CPU burst; 17 bursts to go [Q B7 A9 A0 B0 B2 A1 A7 A8 A2 B9 B6 A5 B5 A4 B8 B1 B3 A3]
time 328ms: Process A6 switching out of CPU; blocking on I/O until time 402ms [Q B7 A9 A0 B0 B2 A1 A7 A8 A2 B9 B6 A5 B5 A4 B8 B1 B3 A3]
time 332ms: Process B7 started using the CPU for 71ms burst [Q A9 A0 B0 B2 A1 A7 A8 A2 B9 B6 A5 B5 A4 B8 B1 B3 A3]
time 402ms: Process A6 completed I/O; added to ready queue [Q A9 A0 B0 B2 A1 A7 A8 A2 B9 B6 A5 B5 A4 B8 B1 B3 A3 A6]
time 403ms: Process B7 completed a CPU burst; 25 bursts to go [Q A9 A0 B0 B2 A1 A7 A8 A2 B9 B6 A5 B5 A4 B8 B1 B3 A3 A6]
time 403ms: Process B7 switching out of CPU; blocking on I/O until time 3453ms [Q A9 A0 B0 B2 A1 A7 A8 A2 B9 B6 A5 B5 A4 B8 B1 B3 A3 A6]
time 407ms: Process A9 started using the CPU for 360ms burst [Q A0 B0 B2 A1 A7 A8 A2 B9 B6 A5 B5 A4 B8 B1 B3 A3 A6]
time 767ms: Process A9 completed a CPU burst; 31 bursts to go [Q A0 B0 B2 A1 A7 A8 A2 B9 B6 A5 B5 A4 B8 B1 B3 A3 A6]
time 767ms: Process A9 switching out of CPU; blocking on I/O until time 809ms [Q A0 B0 B2 A1 A7 A8 A2 B9 B6 A5 B5 A4 B8 B1 B3 A3 A6]
time 771ms: Process A0 started using the CPU for 196ms burst [Q B0 B2 A1 A7 A8 A2 B9 B6 A5 B5 A4 B8 B1 B3 A3 A6]
time 809ms: Process A9 completed I/O; added to ready queue [Q B0 B2 A1 A7 A8 A2 B9 B6 A5 B5 A4 B8 B1 B3 A3 A6 A9]
time 967ms: Process A0 completed a CPU burst; 29 bursts to go [Q B0 B2 A1 A7 A8 A2 B9 B6 A5 B5 A4 B8 B1 B3 A3 A6 A9]
time 967ms: Process A0 switching out of CPU; blocking on I/O until time 1048ms [Q B0 B2 A1 A7 A8 A2 B9 B6 A5 B5 A4 B8 B1 B3 A3 A6 A9]
time 971ms: Process B0 started using the CPU for 216ms burst [Q B2 A1 A7 A8 A2 B9 B6 A5 B5 A4 B8 B1 B3 A3 A6 A9]
time 982ms: Process B4 completed I/O; added to ready queue [Q B2 A1 A7 A8 A2 B9 B6 A5 B5 A4 B8 B1 B3 A3 A6 A9 B4]
time 1048ms: Process A0 completed I/O; added to ready queue [Q B2 A1 A7 A8 A2 B9 B6 A5 B5 A4 B8 B1 B3 A3 A6 A9 B4 A0]
time 1187ms: Process B0 completed a CPU burst; 18 bursts to go [Q B2 A1 A7 A8 A2 B9 B6 A5 B5 A4 B8 B1 B3 A3 A6 A9 B4 A0]
time 1187ms: Process B0 switching out of CPU; blocking on I/O until time 1338ms [Q B2 A1 A7 A8 A2 B9 B6 A5 B5 A4 B8 B1 B3 A3 A6 A9 B4 A0]
time 1191ms: Process B2 started using the CPU for 122ms burst [Q A1 A7 A8 A2 B9 B6 A5 B5 A4 B8 B1 B3 A3 A6 A9 B4 A0]
time 1313ms: Process B2 completed a CPU burst; 14 bursts to go [Q A1 A7 A8 A2 B9 B6 A5 B5 A4 B8 B1 B3 A3 A6 A9 B4 A0]
time 1313ms: Process B2 switching out of CPU; blocking on I/O until time 1835ms [Q A1 A7 A8 A2 B9 B6 A5 B5 A4 B8 B1 B3 A3 A6 A9 B4 A0]
time 1317ms: Process A1 started using the CPU for 632ms burst [Q A7 A8 A2 B9 B6 A5 B5 A4 B8 B1 B3 A3 A6 A9 B4 A0]
time 1338ms: Process B0 completed I/O; added to ready queue [Q A7 A8 A2 B9 B6 A5 B5 A4 B8 B1 B3 A3 A6 A9 B4 A0 B0]
time 1835ms: Process B2 completed I/O; added to ready queue [Q A7 A8 A2 B9 B6 A5 B5 A4 B8 B1 B3 A3 A6 A9 B4 A0 B0 B2]
time 1949ms: Process A1 completed a CPU burst; 11 bursts to go [Q A7 A8 A2 B9 B6 A5 B5 A4 B8 B1 B3 A3 A6 A9 B4 A0 B0 B2]
time 1949ms: Process A1 switching out of CPU; blocking on I/O until time 1989ms [Q A7 A8 A2 B9 B6 A5 B5 A4 B8 B1 B3 A3 A6 A9 B4 A0 B0 B2]
time 1953ms: Process A7 started using the CPU for 84ms burst [Q A8 A2 B9 B6 A5 B5 A4 B8 B1 B3 A3 A6 A9 B4 A0 B0 B2]
time 1989ms: Process A1 completed I/O; added to ready queue [Q A8 A2 B9 B6 A5 B5 A4 B8 B1 B3 A3 A6 A9 B4 A0 B0 B2 A1]
time 2037ms: Process A7 completed a CPU burst; 18 bursts to go [Q A8 A2 B9 B6 A5 B5 A4 B8 B1 B3 A3 A6 A9 B4 A0 B0 B2 A1]
time 2037ms: Process A7 switching out of CPU; blocking on I/O until time 2088ms [Q A8 A2 B9 B6 A5 B5 A4 B8 B1 B3 A3 A6 A9 B4 A0 B0 B2 A1]
time 2041ms: Process A8 started using the CPU for 420ms burst [Q A2 B9 B6 A5 B5 A4 B8 B1 B3 A3 A6 A9 B4 A0 B0 B2 A1]
time 2088ms: Process A7 completed I/O; added to ready queue [Q A2 B9 B6 A5 B5 A4 B8 B1 B3 A3 A6 A9 B4 A0 B0 B2 A1 A7]
time 2461ms: Process A8 completed a CPU burst; 7 bursts to go [Q A2 B9 B6 A5 B5 A4 B8 B1 B3 A3 A6 A9 B4 A0 B0 B2 A1 A7]
time 2461ms: Process A8 switching out of CPU; blocking on I/O until time 2517ms [Q A2 B9 B6 A5 B5 A4 B8 B1 B3 A3 A6 A9 B4 A0 B0 B2 A1 A7]
time 2465ms: Process A2 started using the CPU for 28ms burst [Q B9 B6 A5 B5 A4 B8 B1 B3 A3 A6 A9 B4 A0 B0 B2 A1 A7]
time 2493ms: Process A2 completed a CPU burst; 29 bursts to go [Q B9 B6 A5 B5 A4 B8 B1 B3 A3 A6 A9 B4 A0 B0 B2 A1 A7]
time 2493ms: Process A2 switching out of CPU; blocking on I/O until time 2508ms [Q B9 B6 A5 B5 A4 B8 B1 B3 A3 A6 A9 B4 A0 B0 B2 A1 A7]
time 2497ms: Process B9 started using the CPU for 22ms burst [Q B6 A5 B5 A4 B8 B1 B3 A3 A6 A9 B4 A0 B0 B2 A1 A7]
time 2508ms: Process A2 completed I/O; added to ready queue [Q B6 A5 B5 A4 B8 B1 B3 A3 A6 A9 B4 A0 B0 B2 A1 A7 A2]
time 2517ms: Process A8 completed I/O; added to ready queue [Q B6 A5 B5 A4 B8 B1 B3 A3 A6 A9 B4 A0 B0 B2 A1 A7 A2 A8]
time 2519ms: Process B9 completed a CPU burst; 10 bursts to go [Q B6 A5 B5 A4 B8 B1 B3 A3 A6 A9 B4 A0 B0 B2 A1 A7 A2 A8]
time 2519ms: Process B9 switching out of CPU; blocking on I/O until time 3129ms [Q B6 A5 B5 A4 B8 B1 B3 A3 A6 A9 B4 A0 B0 B2 A1 A7 A2 A8]
time 2523ms: Process B6 started using the CPU for 113ms burst [Q A5 B5 A4 B8 B1 B3 A3 A6 A9 B4 A0 B0 B2 A1 A7 A2 A8]
time 2636ms: Process B6 completed a CPU burst; 4 bursts to go [Q A5 B5 A4 B8 B1 B3 A3 A6 A9 B4 A0 B0 B2 A1 A7 A2 A8]
time 2636ms: Process B6 switching out of CPU; blocking on I/O until time 5862ms [Q A5 B5 A4 B8 B1 B3 A3 A6 A9 B4 A0 B0 B2 A1 A7 A2 A8]
time 2640ms: Process A5 started using the CPU for 196ms burst [Q B5 A4 B8 B1 B3 A3 A6 A9 B4 A0 B0 B2 A1 A7 A2 A8]
time 2836ms: Process A5 completed a CPU burst; 4 bursts to go [Q B5 A4 B8 B1 B3 A3 A6 A9 B4 A0 B0 B2 A1 A7 A2 A8]
time 2836ms: Process A5 switching out of CPU; blocking on I/O until time 2855ms [Q B5 A4 B8 B1 B3 A3 A6 A9 B4 A0 B0 B2 A1 A7 A2 A8]
time 2840ms: Process B5 started using the CPU for 20ms burst [Q A4 B8 B1 B3 A3 A6 A9 B4 A0 B0 B2 A1 A7 A2 A8]
time 2855ms: Process A5 completed I/O; added to ready queue [Q A4 B8 B1 B3 A3 A6 A9 B4 A0 B0 B2 A1 A7 A2 A8 A5]
time 2860ms: Process B5 completed a CPU burst; 29 bursts to go [Q A4 B8 B1 B3 A3 A6 A9 B4 A0 B0 B2 A1 A7 A2 A8 A5]
time 2860ms: Process B5 switching out of CPU; blocking on I/O until time 3110ms [Q A4 B8 B1 B3 A3 A6 A9 B4 A0 B0 B2 A1 A7 A2 A8 A5]
time 2864ms: Process A4 started using the CPU for 300ms burst [Q B8 B1 B3 A3 A6 A9 B4 A0 B0 B2 A1 A7 A2 A8 A5]
time 3110ms: Process B5 completed I/O; added to ready queue [Q B8 B1 B3 A3 A6 A9 B4 A0 B0 B2 A1 A7 A2 A8 A5 B5]
time 3129ms: Process B9 completed I/O; added to ready queue [Q B8 B1 B3 A3 A6 A9 B4 A0 B0 B2 A1 A7 A2 A8 A5 B5 B9]
time 3164ms: Process A4 completed a CPU burst; 3 bursts to go [Q B8 B1 B3 A3 A6 A9 B4 A0 B0 B2 A1 A7 A2 A8 A5 B5 B9]
time 3164ms: Process A4 switching out of CPU; blocking on I/O until time 3255ms [Q B8 B1 B3 A3 A6 A9 B4 A0 B0 B2 A1 A7 A2 A8 A5 B5 B9]
time 3168ms: Process B8 started using the CPU for 308ms burst [Q B1 B3 A3 A6 A9 B4 A0 B0 B2 A1 A7 A2 A8 A5 B5 B9]
time 3255ms: Process A4 completed I/O; added to ready queue [Q B1 B3 A3 A6 A9 B4 A0 B0 B2 A1 A7 A2 A8 A5 B5 B9 A4]
time 3453ms: Process B7 completed I/O; added to ready queue [Q B1 B3 A3 A6 A9 B4 A0 B0 B2 A1 A7 A2 A8 A5 B5 B9 A4 B7]
time 3476ms: Process B8 completed a CPU burst; 19 bursts to go [Q B1 B3 A3 A6 A9 B4 A0 B0 B2 A1 A7 A2 A8 A5 B5 B9 A4 B7]
time 3476ms: Process B8 switching out of CPU; blocking on I/O until time 5758ms [Q B1 B3 A3 A6 A9 B4 A0 B0 B2 A1 A7 A2 A8 A5 B5 B9 A4 B7]
time 3480ms: Process B1 started using the CPU for 3004ms burst [Q B3 A3 A6 A9 B4 A0 B0 B2 A1 A7 A2 A8 A5 B5 B9 A4 B7]
time 5758ms: Process B8 completed I/O; added to ready queue [Q B3 A3 A6 A9 B4 A0 B0 B2 A1 A7 A2 A8 A5 B5 B9 A4 B7 B8]
time 5862ms: Process B6 completed I/O; added to ready queue [Q B3 A3 A6 A9 B4 A0 B0 B2 A1 A7 A2 A8 A5 B5 B9 A4 B7 B8 B6]
time 6484ms: Process B1 completed a CPU burst; 15 bursts to go [Q B3 A3 A6 A9 B4 A0 B0 B2 A1 A7 A2 A8 A5 B5 B9 A4 B7 B8 B6]
time 6484ms: Process B1 switching out of CPU; blocking on I/O until time 6625ms [Q B3 A3 A6 A9 B4 A0 B0 B2 A1 A7 A2 A8 A5 B5 B9 A4 B7 B8 B6]
time 6488ms: Process B3 started using the CPU for 51ms burst [Q A3 A6 A9 B4 A0 B0 B2 A1 A7 A2 A8 A5 B5 B9 A4 B7 B8 B6]
time 6539ms: Process B3 completed a CPU burst; 21 bursts to go [Q A3 A6 A9 B4 A0 B0 B2 A1 A7 A2 A8 A5 B5 B9 A4 B7 B8 B6]
time 6539ms: Process B3 switching out of CPU; blocking on I/O until time 8877ms [Q A3 A6 A9 B4 A0 B0 B2 A1 A7 A2 A8 A5 B5 B9 A4 B7 B8 B6]
time 6543ms: Process A3 started using the CPU for 96ms burst [Q A6 A9 B4 A0 B0 B2 A1 A7 A2 A8 A5 B5 B9 A4 B7 B8 B6]
time 6625ms: Process B1 completed I/O; added to ready queue [Q A6 A9 B4 A0 B0 B2 A1 A7 A2 A8 A5 B5 B9 A4 B7 B8 B6 B1]
time 6639ms: Process A3 completed a CPU burst; 25 bursts to go [Q A6 A9 B4 A0 B0 B2 A1 A7 A2 A8 A5 B5 B9 A4 B7 B8 B6 B1]
time 6639ms: Process A3 switching out of CPU; blocking on I/O until time 7011ms [Q A6 A9 B4 A0 B0 B2 A1 A7 A2 A8 A5 B5 B9 A4 B7 B8 B6 B1]
time 6643ms: Process A6 started using the CPU for 100ms burst [Q A9 B4 A0 B0 B2 A1 A7 A2 A8 A5 B5 B9 A4 B7 B8 B6 B1]
time 6743ms: Process A6 completed a CPU burst; 16 bursts to go [Q A9 B4 A0 B0 B2 A1 A7 A2 A8 A5 B5 B9 A4 B7 B8 B6 B1]
time 6743ms: Process A6 switching out of CPU; blocking on I/O until time 6760ms [Q A9 B4 A0 B0 B2 A1 A7 A2 A8 A5 B5 B9 A4 B7 B8 B6 B1]
time 6747ms: Process A9 started using the CPU for 28ms burst [Q B4 A0 B0 B2 A1 A7 A2 A8 A5 B5 B9 A4 B7 B8 B6 B1]
time 6760ms: Process A6 completed I/O; added to ready queue [Q B4 A0 B0 B2 A1 A7 A2 A8 A5 B5 B9 A4 B7 B8 B6 B1 A6]
time 6775ms: Process A9 completed a CPU burst; 30 bursts to go [Q B4 A0 B0 B2 A1 A7 A2 A8 A5 B5 B9 A4 B7 B8 B6 B1 A6]
time 6775ms: Process A9 switching out of CPU; blocking on I/O until time 6805ms [Q B4 A0 B0 B2 A1 A7 A2 A8 A5 B5 B9 A4 B7 B8 B6 B1 A6]
time 6779ms: Process B4 started using the CPU for 3ms burst [Q A0 B0 B2 A1 A7 A2 A8 A5 B5 B9 A4 B7 B8 B6 B1 A6]
time 6782ms: Process B4 completed a CPU burst; 14 bursts to go [Q A0 B0 B2 A1 A7 A2 A8 A5 B5 B9 A4 B7 B8 B6 B1 A6]
time 6782ms: Process B4 switching out of CPU; blocking on I/O until time 7880ms [Q A0 B0 B2 A1 A7 A2 A8 A5 B5 B9 A4 B7 B8 B6 B1 A6]
time 6786ms: Process A0 started using the CPU for 1096ms burst [Q B0 B2 A1 A7 A2 A8 A5 B5 B9 A4 B7 B8 B6 B1 A6]
time 6805ms: Process A9 completed I/O; added to ready queue [Q B0 B2 A1 A7 A2 A8 A5 B5 B9 A4 B7 B8 B6 B1 A6 A9]
time 7011ms: Process A3 completed I/O; added to ready queue [Q B0 B2 A1 A7 A2 A8 A5 B5 B9 A4 B7 B8 B6 B1 A6 A9 A3]
time 7880ms: Process B4 completed I/O; added to ready queue [Q B0 B2 A1 A7 A2 A8 A5 B5 B9 A4 B7 B8 B6 B1 A6 A9 A3 B4]
time 7882ms: Process A0 completed a CPU burst; 28 bursts to go [Q B0 B2 A1 A7 A2 A8 A5 B5 B9 A4 B7 B8 B6 B1 A6 A9 A3 B4]
time 7882ms: Process A0 switching out of CPU; blocking on I/O until time 7969ms [Q B0 B2 A1 A7 A2 A8 A5 B5 B9 A4 B7 B8 B6 B1 A6 A9 A3 B4]
time 7886ms: Process B0 started using the CPU for 1264ms burst [Q B2 A1 A7 A2 A8 A5 B5 B9 A4 B7 B8 B6 B1 A6 A9 A3 B4]
time 7969ms: Process A0 completed I/O; added to ready queue [Q B2 A1 A7 A2 A8 A5 B5 B9 A4 B7 B8 B6 B1 A6 A9 A3 B4 A0]
time 8877ms: Process B3 completed I/O; added to ready queue [Q B2 A1 A7 A2 A8 A5 B5 B9 A4 B7 B8 B6 B1 A6 A9 A3 B4 A0 B3]
time 9150ms: Process B0 completed a CPU burst; 17 bursts to go [Q B2 A1 A7 A2 A8 A5 B5 B9 A4 B7 B8 B6 B1 A6 A9 A3 B4 A0 B3]
time 9150ms: Process B0 switching out of CPU; blocking on I/O until time 9161ms [Q B2 A1 A7 A2 A8 A5 B5 B9 A4 B7 B8 B6 B1 A6 A9 A3 B4 A0 B3]
time 9154ms: Process B2 started using the CPU for 183ms burst [Q A1 A7 A2 A8 A5 B5 B9 A4 B7 B8 B6 B1 A6 A9 A3 B4 A0 B3]
time 9161ms: Process B0 completed I/O; added to ready queue [Q A1 A7 A2 A8 A5 B5 B9 A4 B7 B8 B6 B1 A6 A9 A3 B4 A0 B3 B0]
time 9337ms: Process B2 completed a CPU burst; 13 bursts to go [Q A1 A7 A2 A8 A5 B5 B9 A4 B7 B8 B6 B1 A6 A9 A3 B4 A0 B3 B0]
time 9337ms: Process B2 switching out of CPU; blocking on I/O until time 9651ms [Q A1 A7 A2 A8 A5 B5 B9 A4 B7 B8 B6 B1 A6 A9 A3 B4 A0 B3 B0]
time 9341ms: Process A1 started using the CPU for 200ms burst [Q A7 A2 A8 A5 B5 B9 A4 B7 B8 B6 B1 A6 A9 A3 B4 A0 B3 B0]
time 9541ms: Process A1 completed a CPU burst; 10 bursts to go [Q A7 A2 A8 A5 B5 B9 A4 B7 B8 B6 B1 A6 A9 A3 B4 A0 B3 B0]
time 9541ms: Process A1 switching out of CPU; blocking on I/O until time 9575ms [Q A7 A2 A8 A5 B5 B9 A4 B7 B8 B6 B1 A6 A9 A3 B4 A0 B3 B0]
time 9545ms: Process A7 started using the CPU for 768ms burst [Q A2 A8 A5 B5 B9 A4 B7 B8 B6 B1 A6 A9 A3 B4 A0 B3 B0]
time 9575ms: Process A1 completed I/O; added to ready queue [Q A2 A8 A5 B5 B9 A4 B7 B8 B6 B1 A6 A9 A3 B4 A0 B3 B0 A1]
time 9651ms: Process B2 completed I/O; added to ready queue [Q A2 A8 A5 B5 B9 A4 B7 B8 B6 B1 A6 A9 A3 B4 A0 B3 B0 A1 B2]
time 10313ms: Process A7 completed a CPU burst; 17 bursts to go [Q A2 A8 A5 B5 B9 A4 B7 B8 B6 B1 A6 A9 A3 B4 A0 B3 B0 A1 B2]
time 10313ms: Process A7 switching out of CPU; blocking on I/O until time 10436ms [Q A2 A8 A5 B5 B9 A4 B7 B8 B6 B1 A6 A9 A3 B4 A0 B3 B0 A1 B2]
time 10317ms: Process A2 started using the CPU for 444ms burst [Q A8 A5 B5 B9 A4 B7 B8 B6 B1 A6 A9 A3 B4 A0 B3 B0 A1 B2]
time 10436ms: Process A7 completed I/O; added to ready queue [Q A8 A5 B5 B9 A4 B7 B8 B6 B1 A6 A9 A3 B4 A0 B3 B0 A1 B2 A7]
time 10761ms: Process A2 completed a CPU burst; 28 bursts to go [Q A8 A5 B5 B9 A4 B7 B8 B6 B1 A6 A9 A3 B4 A0 B3 B0 A1 B2 A7]
time 10761ms: Process A2 switching out of CPU; blocking on I/O until time 11222ms [Q A8 A5 B5 B9 A4 B7 B8 B6 B1 A6 A9 A3 B4 A0 B3 B0 A1 B2 A7]
time 10765ms: Process A8 started using the CPU for 176ms burst [Q A5 B5 B9 A4 B7 B8 B6 B1 A6 A9 A3 B4 A0 B3 B0 A1 B2 A7]
time 10941ms: Process A8 completed a CPU burst; 6 bursts to go [Q A5 B5 B9 A4 B7 B8 B6 B1 A6 A9 A3 B4 A0 B3 B0 A1 B2 A7]
time 10941ms: Process A8 switching out of CPU; blocking on I/O until time 10981ms [Q A5 B5 B9 A4 B7 B8 B6 B1 A6 A9 A3 B4 A0 B3 B0 A1 B2 A7]
time 10945ms: Process A5 started using the CPU for 140ms burst [Q B5 B9 A4 B7 B8 B6 B1 A6 A9 A3 B4 A0 B3 B0 A1 B2 A7]
time 10981ms: Process A8 completed I/O; added to ready queue [Q B5 B9 A4 B7 B8 B6 B1 A6 A9 A3 B4 A0 B3 B0 A1 B2 A7 A8]
time 11085ms: Process A5 completed a CPU burst; 3 bursts to go [Q B5 B9 A4 B7 B8 B6 B1 A6 A9 A3 B4 A0 B3 B0 A1 B2 A7 A8]
time 11085ms: Process A5 switching out of CPU; blocking on I/O until time 11199ms [Q B5 B9 A4 B7 B8 B6 B1 A6 A9 A3 B4 A0 B3 B0 A1 B2 A7 A8]
time 11089ms: Process B5 started using the CPU for 85ms burst [Q B9 A4 B7 B8 B6 B1 A6 A9 A3 B4 A0 B3 B0 A1 B2 A7 A8]
time 11174ms: Process B5 completed a CPU burst; 28 bursts to go [Q B9 A4 B7 B8 B6 B1 A6 A9 A3 B4 A0 B3 B0 A1 B2 A7 A8]
time 11174ms: Process B5 switching out of CPU; blocking on I/O until time 11416ms [Q B9 A4 B7 B8 B6 B1 A6 A9 A3 B4 A0 B3 B0 A1 B2 A7 A8]
time 11178ms: Process B9 started using the CPU for 142ms burst [Q A4 B7 B8 B6 B1 A6 A9 A3 B4 A0 B3 B0 A1 B2 A7 A8]
time 11199ms: Process A5 completed I/O; added to ready queue [Q A4 B7 B8 B6 B1 A6 A9 A3 B4 A0 B3 B0 A1 B2 A7 A8 A5]
time 11222ms: Process A2 completed I/O; added to ready queue [Q A4 B7 B8 B6 B1 A6 A9 A3 B4 A0 B3 B0 A1 B2 A7 A8 A5 A2]
time 11320ms: Process B9 completed a CPU burst; 9 bursts to go [Q A4 B7 B8 B6 B1 A6 A9 A3 B4 A0 B3 B0 A1 B2 A7 A8 A5 A2]
time 11320ms: Process B9 switching out of CPU; blocking on I/O until time 11394ms [Q A4 B7 B8 B6 B1 A6 A9 A3 B4 A0 B3 B0 A1 B2 A7 A8 A5 A2]
time 11324ms: Process A4 started using the CPU for 20ms burst [Q B7 B8 B6 B1 A6 A9 A3 B4 A0 B3 B0 A1 B2 A7 A8 A5 A2]
time 11344ms: Process A4 completed a CPU burst; 2 bursts to go [Q B7 B8 B6 B1 A6 A9 A3 B4 A0 B3 B0 A1 B2 A7 A8 A5 A2]
time 11344ms: Process A4 switching out of CPU; blocking on I/O until time 11506ms [Q B7 B8 B6 B1 A6 A9 A3 B4 A0 B3 B0 A1 B2 A7 A8 A5 A2]
time 11348ms: Process B7 started using the CPU for 20ms burst [Q B8 B6 B1 A6 A9 A3 B4 A0 B3 B0 A1 B2 A7 A8 A5 A2]
time 11368ms: Process B7 completed a CPU burst; 24 bursts to go [Q B8 B6 B1 A6 A9 A3 B4 A0 B3 B0 A1 B2 A7 A8 A5 A2]
time 11368ms: Process B7 switching out of CPU; blocking on I/O until time 11410ms [Q B8 B6 B1 A6 A9 A3 B4 A0 B3 B0 A1 B2 A7 A8 A5 A2]
time 11372ms: Process B8 started using the CPU for 18ms burst [Q B6 B1 A6 A9 A3 B4 A0 B3 B0 A1 B2 A7 A8 A5 A2]
time 11390ms: Process B8 completed a CPU burst; 18 bursts to go [Q B6 B1 A6 A9 A3 B4 A0 B3 B0 A1 B2 A7 A8 A5 A2]
time 11390ms: Process B8 switching out of CPU; blocking on I/O until time 11520ms [Q B6 B1 A6 A9 A3 B4 A0 B3 B0 A1 B2 A7 A8 A5 A2]
time 11394ms: Process B6 started using the CPU for 142ms burst [Q B1 A6 A9 A3 B4 A0 B3 B0 A1 B2 A7 A8 A5 A2]
time 11394ms: Process B9 completed I/O; added to ready queue [Q B1 A6 A9 A3 B4 A0 B3 B0 A1 B2 A7 A8 A5 A2 B9]
time 11410ms: Process B7 completed I/O; added to ready queue [Q B1 A6 A9 A3 B4 A0 B3 B0 A1 B2 A7 A8 A5 A2 B9 B7]
time 11416ms: Process B5 completed I/O; added to ready queue [Q B1 A6 A9 A3 B4 A0 B3 B0 A1 B2 A7 A8 A5 A2 B9 B7 B5]
time 11506ms: Process A4 completed I/O; added to ready queue [Q B1 A6 A9 A3 B4 A0 B3 B0 A1 B2 A7 A8 A5 A2 B9 B7 B5 A4]
time 11520ms: Process B8 completed I/O; added to ready queue [Q B1 A6 A9 A3 B4 A0 B3 B0 A1 B2 A7 A8 A5 A2 B9 B7 B5 A4 B8]
time 11536ms: Process B6 completed a CPU burst; 3 bursts to go [Q B1 A6 A9 A3 B4 A0 B3 B0 A1 B2 A7 A8 A5 A2 B9 B7 B5 A4 B8]
time 11536ms: Process B6 switching out of CPU; blocking on I/O until time 12410ms [Q B1 A6 A9 A3 B4 A0 B3 B0 A1 B2 A7 A8 A5 A2 B9 B7 B5 A4 B8]
time 11540ms: Process B1 started using the CPU for 48ms burst [Q A6 A9 A3 B4 A0 B3 B0 A1 B2 A7 A8 A5 A2 B9 B7 B5 A4 B8]
time 11588ms: Process B1 completed a CPU burst; 14 bursts to go [Q A6 A9 A3 B4 A0 B3 B0 A1 B2 A7 A8 A5 A2 B9 B7 B5 A4 B8]
time 11588ms: Process B1 switching out of CPU; blocking on I/O until time 11610ms [Q A6 A9 A3 B4 A0 B3 B0 A1 B2 A7 A8 A5 A2 B9 B7 B5 A4 B8]
time 11592ms: Process A6 started using the CPU for 344ms burst [Q A9 A3 B4 A0 B3 B0 A1 B2 A7 A8 A5 A2 B9 B7 B5 A4 B8]
time 11610ms: Process B1 completed I/O; added to ready queue [Q A9 A3 B4 A0 B3 B0 A1 B2 A7 A8 A5 A2 B9 B7 B5 A4 B8 B1]
time 11936ms: Process A6 completed a CPU burst; 15 bursts to go [Q A9 A3 B4 A0 B3 B0 A1 B2 A7 A8 A5 A2 B9 B7 B5 A4 B8 B1]
time 11936ms: Process A6 switching out of CPU; blocking on I/O until time 11979ms [Q A9 A3 B4 A0 B3 B0 A1 B2 A7 A8 A5 A2 B9 B7 B5 A4 B8 B1]
time 11940ms: Process A9 started using the CPU for 308ms burst [Q A3 B4 A0 B3 B0 A1 B2 A7 A8 A5 A2 B9 B7 B5 A4 B8 B1]
time 11979ms: Process A6 completed I/O; added to ready queue [Q A3 B4 A0 B3 B0 A1 B2 A7 A8 A5 A2 B9 B7 B5 A4 B8 B1 A6]
time 12248ms: Process A9 completed a CPU burst; 29 bursts to go [Q A3 B4 A0 B3 B0 A1 B2 A7 A8 A5 A2 B9 B7 B5 A4 B8 B1 A6]
time 12248ms: Process A9 switching out of CPU; blocking on I/O until time 12283ms [Q A3 B4 A0 B3 B0 A1 B2 A7 A8 A5 A2 B9 B7 B5 A4 B8 B1 A6]
time 12252ms: Process A3 started using the CPU for 308ms burst [Q B4 A0 B3 B0 A1 B2 A7 A8 A5 A2 B9 B7 B5 A4 B8 B1 A6]
time 12283ms: Process A9 completed I/O; added to ready queue [Q B4 A0 B3 B0 A1 B2 A7 A8 A5 A2 B9 B7 B5 A4 B8 B1 A6 A9]
time 12410ms: Process B6 completed I/O; added to ready queue [Q B4 A0 B3 B0 A1 B2 A7 A8 A5 A2 B9 B7 B5 A4 B8 B1 A6 A9 B6]
time 12560ms: Process A3 completed a CPU burst; 24 bursts to go [Q B4 A0 B3 B0 A1 B2 A7 A8 A5 A2 B9 B7 B5 A4 B8 B1 A6 A9 B6]
time 12560ms: Process A3 switching out of CPU; blocking on I/O until time 12650ms [Q B4 A0 B3 B0 A1 B2 A7 A8 A5 A2 B9 B7 B5 A4 B8 B1 A6 A9 B6]
time 12564ms: Process B4 started using the CPU for 285ms burst [Q A0 B3 B0 A1 B2 A7 A8 A5 A2 B9 B7 B5 A4 B8 B1 A6 A9 B6]
time 12650ms: Process A3 completed I/O; added to ready queue [Q A0 B3 B0 A1 B2 A7 A8 A5 A2 B9 B7 B5 A4 B8 B1 A6 A9 B6 A3]
time 12849ms: Process B4 completed a CPU burst; 13 bursts to go [Q A0 B3 B0 A1 B2 A7 A8 A5 A2 B9 B7 B5 A4 B8 B1 A6 A9 B6 A3]
time 12849ms: Process B4 switching out of CPU; blocking on I/O until time 13075ms [Q A0 B3 B0 A1 B2 A7 A8 A5 A2 B9 B7 B5 A4 B8 B1 A6 A9 B6 A3]
time 12853ms: Process A0 started using the CPU for 912ms burst [Q B3 B0 A1 B2 A7 A8 A5 A2 B9 B7 B5 A4 B8 B1 A6 A9 B6 A3]
time 13075ms: Process B4 completed I/O; added to ready queue [Q B3 B0 A1 B2 A7 A8 A5 A2 B9 B7 B5 A4 B8 B1 A6 A9 B6 A3 B4]
time 13765ms: Process A0 completed a CPU burst; 27 bursts to go [Q B3 B0 A1 B2 A7 A8 A5 A2 B9 B7 B5 A4 B8 B1 A6 A9 B6 A3 B4]
time 13765ms: Process A0 switching out of CPU; blocking on I/O until time 13773ms [Q B3 B0 A1 B2 A7 A8 A5 A2 B9 B7 B5 A4 B8 B1 A6 A9 B6 A3 B4]
time 13769ms: Process B3 started using the CPU for 129ms burst [Q B0 A1 B2 A7 A8 A5 A2 B9 B7 B5 A4 B8 B1 A6 A9 B6 A3 B4]
time 13773ms: Process A0 completed I/O; added to ready queue [Q B0 A1 B2 A7 A8 A5 A2 B9 B7 B5 A4 B8 B1 A6 A9 B6 A3 B4 A0]
time 13898ms: Process B3 completed a CPU burst; 20 bursts to go [Q B0 A1 B2 A7 A8 A5 A2 B9 B7 B5 A4 B8 B1 A6 A9 B6 A3 B4 A0]
time 13898ms: Process B3 switching out of CPU; blocking on I/O until time 15260ms [Q B0 A1 B2 A7 A8 A5 A2 B9 B7 B5 A4 B8 B1 A6 A9 B6 A3 B4 A0]
time 13902ms: Process B0 started using the CPU for 340ms burst [Q A1 B2 A7 A8 A5 A2 B9 B7 B5 A4 B8 B1 A6 A9 B6 A3 B4 A0]
time 14242ms: Process B0 completed a CPU burst; 16 bursts to go [Q A1 B2 A7 A8 A5 A2 B9 B7 B5 A4 B8 B1 A6 A9 B6 A3 B4 A0]
time 14242ms: Process B0 switching out of CPU; blocking on I/O until time 14336ms [Q A1 B2 A7 A8 A5 A2 B9 B7 B5 A4 B8 B1 A6 A9 B6 A3 B4 A0]
time 14246ms: Process A1 started using the CPU for 608ms burst [Q B2 A7 A8 A5 A2 B9 B7 B5 A4 B8 B1 A6 A9 B6 A3 B4 A0]
time 14336ms: Process B0 completed I/O; added to ready queue [Q B2 A7 A8 A5 A2 B9 B7 B5 A4 B8 B1 A6 A9 B6 A3 B4 A0 B0]
time 14854ms: Process A1 completed a CPU burst; 9 bursts to go [Q B2 A7 A8 A5 A2 B9 B7 B5 A4 B8 B1 A6 A9 B6 A3 B4 A0 B0]
time 14854ms: Process A1 switching out of CPU; blocking on I/O until time 14881ms [Q B2 A7 A8 A5 A2 B9 B7 B5 A4 B8 B1 A6 A9 B6 A3 B4 A0 B0]
time 14858ms: Process B2 started using the CPU for 219ms burst [Q A7 A8 A5 A2 B9 B7 B5 A4 B8 B1 A6 A9 B6 A3 B4 A0 B0]
time 14881ms: Process A1 completed I/O; added to ready queue [Q A7 A8 A5 A2 B9 B7 B5 A4 B8 B1 A6 A9 B6 A3 B4 A0 B0 A1]
time 15077ms: Process B2 completed a CPU burst; 12 bursts to go [Q A7 A8 A5 A2 B9 B7 B5 A4 B8 B1 A6 A9 B6 A3 B4 A0 B0 A1]
time 15077ms: Process B2 switching out of CPU; blocking on I/O until time 15351ms [Q A7 A8 A5 A2 B9 B7 B5 A4 B8 B1 A6 A9 B6 A3 B4 A0 B0 A1]
time 15081ms: Process A7 started using the CPU for 1388ms burst [Q A8 A5 A2 B9 B7 B5 A4 B8 B1 A6 A9 B6 A3 B4 A0 B0 A1]
time 15260ms: Process B3 completed I/O; added to ready queue [Q A8 A5 A2 B9 B7 B5 A4 B8 B1 A6 A9 B6 A3 B4 A0 B0 A1 B3]
time 15351ms: Process B2 completed I/O; added to ready queue [Q A8 A5 A2 B9 B7 B5 A4 B8 B1 A6 A9 B6 A3 B4 A0 B0 A1 B3 B2]
time 16469ms: Process A7 completed a CPU burst; 16 bursts to go [Q A8 A5 A2 B9 B7 B5 A4 B8 B1 A6 A9 B6 A3 B4 A0 B0 A1 B3 B2]
time 16469ms: Process A7 switching out of CPU; blocking on I/O until time 16560ms [Q A8 A5 A2 B9 B7 B5 A4 B8 B1 A6 A9 B6 A3 B4 A0 B0 A1 B3 B2]
time 16473ms: Process A8 started using the CPU for 340ms burst [Q A5 A2 B9 B7 B5 A4 B8 B1 A6 A9 B6 A3 B4 A0 B0 A1 B3 B2]
time 16560ms: Process A7 completed I/O; added to ready queue [Q A5 A2 B9 B7 B5 A4 B8 B1 A6 A9 B6 A3 B4 A0 B0 A1 B3 B2 A7]
time 16813ms: Process A8 completed a CPU burst; 5 bursts to go [Q A5 A2 B9 B7 B5 A4 B8 B1 A6 A9 B6 A3 B4 A0 B0 A1 B3 B2 A7]
time 16813ms: Process A8 switching out of CPU; blocking on I/O until time 16880ms [Q A5 A2 B9 B7 B5 A4 B8 B1 A6 A9 B6 A3 B4 A0 B0 A1 B3 B2 A7]
time 16817ms: Process A5 started using the CPU for 200ms burst [Q A2 B9 B7 B5 A4 B8 B1 A6 A9 B6 A3 B4 A0 B0 A1 B3 B2 A7]
time 16880ms: Process A8 completed I/O; added to ready queue [Q A2 B9 B7 B5 A4 B8 B1 A6 A9 B6 A3 B4 A0 B0 A1 B3 B2 A7 A8]
time 17017ms: Process A5 completed a CPU burst; 2 bursts to go [Q A2 B9 B7 B5 A4 B8 B1 A6 A9 B6 A3 B4 A0 B0 A1 B3 B2 A7 A8]
time 17017ms: Process A5 switching out of CPU; blocking on I/O until time 17085ms [Q A2 B9 B7 B5 A4 B8 B1 A6 A9 B6 A3 B4 A0 B0 A1 B3 B2 A7 A8]
time 17021ms: Process A2 started using the CPU for 760ms burst [Q B9 B7 B5 A4 B8 B1 A6 A9 B6 A3 B4 A0 B0 A1 B3 B2 A7 A8]
time 17085ms: Process A5 completed I/O; added to ready queue [Q B9 B7 B5 A4 B8 B1 A6 A9 B6 A3 B4 A0 B0 A1 B3 B2 A7 A8 A5]
time 17781ms: Process A2 completed a CPU burst; 27 bursts to go [Q B9 B7 B5 A4 B8 B1 A6 A9 B6 A3 B4 A0 B0 A1 B3 B2 A7 A8 A5]
time 17781ms: Process A2 switching out of CPU; blocking on I/O until time 18033ms [Q B9 B7 B5 A4 B8 B1 A6 A9 B6 A3 B4 A0 B0 A1 B3 B2 A7 A8 A5]
time 17785ms: Process B9 started using the CPU for 64ms burst [Q B7 B5 A4 B8 B1 A6 A9 B6 A3 B4 A0 B0 A1 B3 B2 A7 A8 A5]
time 17849ms: Process B9 completed a CPU burst; 8 bursts to go [Q B7 B5 A4 B8 B1 A6 A9 B6 A3 B4 A0 B0 A1 B3 B2 A7 A8 A5]
time 17849ms: Process B9 switching out of CPU; blocking on I/O until time 18691ms [Q B7 B5 A4 B8 B1 A6 A9 B6 A3 B4 A0 B0 A1 B3 B2 A7 A8 A5]
time 17853ms: Process B7 started using the CPU for 3ms burst [Q B5 A4 B8 B1 A6 A9 B6 A3 B4 A0 B0 A1 B3 B2 A7 A8 A5]
time 17856ms: Process B7 completed a CPU burst; 23 bursts to go [Q B5 A4 B8 B1 A6 A9 B6 A3 B4 A0 B0 A1 B3 B2 A7 A8 A5]
time 17856ms: Process B7 switching out of CPU; blocking on I/O until time 20818ms [Q B5 A4 B8 B1 A6 A9 B6 A3 B4 A0 B0 A1 B3 B2 A7 A8 A5]
time 17860ms: Process B5 started using the CPU for 20ms burst [Q A4 B8 B1 A6 A9 B6 A3 B4 A0 B0 A1 B3 B2 A7 A8 A5]
time 17880ms: Process B5 completed a CPU burst; 27 bursts to go [Q A4 B8 B1 A6 A9 B6 A3 B4 A0 B0 A1 B3 B2 A7 A8 A5]
time 17880ms: Process B5 switching out of CPU; blocking on I/O until time 18306ms [Q A4 B8 B1 A6 A9 B6 A3 B4 A0 B0 A1 B3 B2 A7 A8 A5]
time 17884ms: Process A4 started using the CPU for 1248ms burst [Q B8 B1 A6 A9 B6 A3 B4 A0 B0 A1 B3 B2 A7 A8 A5]
time 18033ms: Process A2 completed I/O; added to ready queue [Q B8 B1 A6 A9 B6 A3 B4 A0 B0 A1 B3 B2 A7 A8 A5 A2]
time 18306ms: Process B5 completed I/O; added to ready queue [Q B8 B1 A6 A9 B6 A3 B4 A0 B0 A1 B3 B2 A7 A8 A5 A2 B5]
time 18691ms: Process B9 completed I/O; added to ready queue [Q B8 B1 A6 A9 B6 A3 B4 A0 B0 A1 B3 B2 A7 A8 A5 A2 B5 B9]
time 19132ms: Process A4 completed a CPU burst; 1 burst to go [Q B8 B1 A6 A9 B6 A3 B4 A0 B0 A1 B3 B2 A7 A8 A5 A2 B5 B9]
time 19132ms: Process A4 switching out of CPU; blocking on I/O until time 19158ms [Q B8 B1 A6 A9 B6 A3 B4 A0 B0 A1 B3 B2 A7 A8 A5 A2 B5 B9]
time 19136ms: Process B8 started using the CPU for 75ms burst [Q B1 A6 A9 B6 A3 B4 A0 B0 A1 B3 B2 A7 A8 A5 A2 B5 B9]
time 19158ms: Process A4 completed I/O; added to ready queue [Q B1 A6 A9 B6 A3 B4 A0 B0 A1 B3 B2 A7 A8 A5 A2 B5 B9 A4]
time 19211ms: Process B8 completed a CPU burst; 17 bursts to go [Q B1 A6 A9 B6 A3 B4 A0 B0 A1 B3 B2 A7 A8 A5 A2 B5 B9 A4]
time 19211ms: Process B8 switching out of CPU; blocking on I/O until time 19477ms [Q B1 A6 A9 B6 A3 B4 A0 B0 A1 B3 B2 A7 A8 A5 A2 B5 B9 A4]
time 19215ms: Process B1 started using the CPU for 44ms burst [Q A6 A9 B6 A3 B4 A0 B0 A1 B3 B2 A7 A8 A5 A2 B5 B9 A4]
time 19259ms: Process B1 completed a CPU burst; 13 bursts to go [Q A6 A9 B6 A3 B4 A0 B0 A1 B3 B2 A7 A8 A5 A2 B5 B9 A4]
time 19259ms: Process B1 switching out of CPU; blocking on I/O until time 19337ms [Q A6 A9 B6 A3 B4 A0 B0 A1 B3 B2 A7 A8 A5 A2 B5 B9 A4]
time 19263ms: Process A6 started using the CPU for 756ms burst [Q A9 B6 A3 B4 A0 B0 A1 B3 B2 A7 A8 A5 A2 B5 B9 A4]
time 19337ms: Process B1 completed I/O; added to ready queue [Q A9 B6 A3 B4 A0 B0 A1 B3 B2 A7 A8 A5 A2 B5 B9 A4 B1]
time 19477ms: Process B8 completed I/O; added to ready queue [Q A9 B6 A3 B4 A0 B0 A1 B3 B2 A7 A8 A5 A2 B5 B9 A4 B1 B8]
time 20019ms: Process A6 completed a CPU burst; 14 bursts to go [Q A9 B6 A3 B4 A0 B0 A1 B3 B2 A7 A8 A5 A2 B5 B9 A4 B1 B8]
time 20019ms: Process A6 switching out of CPU; blocking on I/O until time 20139ms [Q A9 B6 A3 B4 A0 B0 A1 B3 B2 A7 A8 A5 A2 B5 B9 A4 B1 B8]
time 20023ms: Process A9 started using the CPU for 16ms burst [Q B6 A3 B4 A0 B0 A1 B3 B2 A7 A8 A5 A2 B5 B9 A4 B1 B8]
time 20039ms: Process A9 completed a CPU burst; 28 bursts to go [Q B6 A3 B4 A0 B0 A1 B3 B2 A7 A8 A5 A2 B5 B9 A4 B1 B8]
time 20039ms: Process A9 switching out of CPU; blocking on I/O until time 20055ms [Q B6 A3 B4 A0 B0 A1 B3 B2 A7 A8 A5 A2 B5 B9 A4 B1 B8]
time 20043ms: Process B6 started using the CPU for 235ms burst [Q A3 B4 A0 B0 A1 B3 B2 A7 A8 A5 A2 B5 B9 A4 B1 B8]
time 20055ms: Process A9 completed I/O; added to ready queue [Q A3 B4 A0 B0 A1 B3 B2 A7 A8 A5 A2 B5 B9 A4 B1 B8 A9]
time 20139ms: Process A6 completed I/O; added to ready queue [Q A3 B4 A0 B0 A1 B3 B2 A7 A8 A5 A2 B5 B9 A4 B1 B8 A9 A6]
time 20278ms: Process B6 completed a CPU burst; 2 bursts to go [Q A3 B4 A0 B0 A1 B3 B2 A7 A8 A5 A2 B5 B9 A4 B1 B8 A9 A6]
time 20278ms: Process B6 switching out of CPU; blocking on I/O until time 21240ms [Q A3 B4 A0 B0 A1 B3 B2 A7 A8 A5 A2 B5 B9 A4 B1 B8 A9 A6]
time 20282ms: Process A3 started using the CPU for 12ms burst [Q B4 A0 B0 A1 B3 B2 A7 A8 A5 A2 B5 B9 A4 B1 B8 A9 A6]
time 20294ms: Process A3 completed a CPU burst; 23 bursts to go [Q B4 A0 B0 A1 B3 B2 A7 A8 A5 A2 B5 B9 A4 B1 B8 A9 A6]
time 20294ms: Process A3 switching out of CPU; blocking on I/O until time 20359ms [Q B4 A0 B0 A1 B3 B2 A7 A8 A5 A2 B5 B9 A4 B1 B8 A9 A6]
time 20298ms: Process B4 started using the CPU for 70ms burst [Q A0 B0 A1 B3 B2 A7 A8 A5 A2 B5 B9 A4 B1 B8 A9 A6]
time 20359ms: Process A3 completed I/O; added to ready queue [Q A0 B0 A1 B3 B2 A7 A8 A5 A2 B5 B9 A4 B1 B8 A9 A6 A3]
time 20368ms: Process B4 completed a CPU burst; 12 bursts to go [Q A0 B0 A1 B3 B2 A7 A8 A5 A2 B5 B9 A4 B1 B8 A9 A6 A3]
time 20368ms: Process B4 switching out of CPU; blocking on I/O until time 20538ms [Q A0 B0 A1 B3 B2 A7 A8 A5 A2 B5 B9 A4 B1 B8 A9 A6 A3]
time 20372ms: Process A0 started using the CPU for 1024ms burst [Q B0 A1 B3 B2 A7 A8 A5 A2 B5 B9 A4 B1 B8 A9 A6 A3]
time 20538ms: Process B4 completed I/O; added to ready queue [Q B0 A1 B3 B2 A7 A8 A5 A2 B5 B9 A4 B1 B8 A9 A6 A3 B4]
time 20818ms: Process B7 completed I/O; added to ready queue [Q B0 A1 B3 B2 A7 A8 A5 A2 B5 B9 A4 B1 B8 A9 A6 A3 B4 B7]
time 21240ms: Process B6 completed I/O; added to ready queue [Q B0 A1 B3 B2 A7 A8 A5 A2 B5 B9 A4 B1 B8 A9 A6 A3 B4 B7 B6]
time 21396ms: Process A0 completed a CPU burst; 26 bursts to go [Q B0 A1 B3 B2 A7 A8 A5 A2 B5 B9 A4 B1 B8 A9 A6 A3 B4 B7 B6]
time 21396ms: Process A0 switching out of CPU; blocking on I/O until time 21535ms [Q B0 A1 B3 B2 A7 A8 A5 A2 B5 B9 A4 B1 B8 A9 A6 A3 B4 B7 B6]
time 21400ms: Process B0 started using the CPU for 228ms burst [Q A1 B3 B2 A7 A8 A5 A2 B5 B9 A4 B1 B8 A9 A6 A3 B4 B7 B6]
time 21535ms: Process A0 completed I/O; added to ready queue [Q A1 B3 B2 A7 A8 A5 A2 B5 B9 A4 B1 B8 A9 A6 A3 B4 B7 B6 A0]
time 21628ms: Process B0 completed a CPU burst; 15 bursts to go [Q A1 B3 B2 A7 A8 A5 A2 B5 B9 A4 B1 B8 A9 A6 A3 B4 B7 B6 A0]
time 21628ms: Process B0 switching out of CPU; blocking on I/O until time 21747ms [Q A1 B3 B2 A7 A8 A5 A2 B5 B9 A4 B1 B8 A9 A6 A3 B4 B7 B6 A0]
time 21632ms: Process A1 started using the CPU for 532ms burst [Q B3 B2 A7 A8 A5 A2 B5 B9 A4 B1 B8 A9 A6 A3 B4 B7 B6 A0]
time 21747ms: Process B0 completed I/O; added to ready queue [Q B3 B2 A7 A8 A5 A2 B5 B9 A4 B1 B8 A9 A6 A3 B4 B7 B6 A0 B0]
time 22164ms: Process A1 completed a CPU burst; 8 bursts to go [Q B3 B2 A7 A8 A5 A2 B5 B9 A4 B1 B8 A9 A6 A3 B4 B7 B6 A0 B0]
time 22164ms: Process A1 switching out of CPU; blocking on I/O until time 22183ms [Q B3 B2 A7 A8 A5 A2 B5 B9 A4 B1 B8 A9 A6 A3 B4 B7 B6 A0 B0]
time 22168ms: Process B3 started using the CPU for 4ms burst [Q B2 A7 A8 A5 A2 B5 B9 A4 B1 B8 A9 A6 A3 B4 B7 B6 A0 B0]
time 22172ms: Process B3 completed a CPU burst; 19 bursts to go [Q B2 A7 A8 A5 A2 B5 B9 A4 B1 B8 A9 A6 A3 B4 B7 B6 A0 B0]
time 22172ms: Process B3 switching out of CPU; blocking on I/O until time 22326ms [Q B2 A7 A8 A5 A2 B5 B9 A4 B1 B8 A9 A6 A3 B4 B7 B6 A0 B0]
time 22176ms: Process B2 started using the CPU for 123ms burst [Q A7 A8 A5 A2 B5 B9 A4 B1 B8 A9 A6 A3 B4 B7 B6 A0 B0]
time 22183ms: Process A1 completed I/O; added to ready queue [Q A7 A8 A5 A2 B5 B9 A4 B1 B8 A9 A6 A3 B4 B7 B6 A0 B0 A1]
time 22299ms: Process B2 completed a CPU burst; 11 bursts to go [Q A7 A8 A5 A2 B5 B9 A4 B1 B8 A9 A6 A3 B4 B7 B6 A0 B0 A1]
time 22299ms: Process B2 switching out of CPU; blocking on I/O until time 22373ms [Q A7 A8 A5 A2 B5 B9 A4 B1 B8 A9 A6 A3 B4 B7 B6 A0 B0 A1]
time 22303ms: Process A7 started using the CPU for 464ms burst [Q A8 A5 A2 B5 B9 A4 B1 B8 A9 A6 A3 B4 B7 B6 A0 B0 A1]
time 22326ms: Process B3 completed I/O; added to ready queue [Q A8 A5 A2 B5 B9 A4 B1 B8 A9 A6 A3 B4 B7 B6 A0 B0 A1 B3]
time 22373ms: Process B2 completed I/O; added to ready queue [Q A8 A5 A2 B5 B9 A4 B1 B8 A9 A6 A3 B4 B7 B6 A0 B0 A1 B3 B2]
time 22767ms: Process A7 completed a CPU burst; 15 bursts to go [Q A8 A5 A2 B5 B9 A4 B1 B8 A9 A6 A3 B4 B7 B6 A0 B0 A1 B3 B2]
time 22767ms: Process A7 switching out of CPU; blocking on I/O until time 22771ms [Q A8 A5 A2 B5 B9 A4 B1 B8 A9 A6 A3 B4 B7 B6 A0 B0 A1 B3 B2]
time 22771ms: Process A8 started using the CPU for 820ms burst [Q A5 A2 B5 B9 A4 B1 B8 A9 A6 A3 B4 B7 B6 A0 B0 A1 B3 B2]
time 22771ms: Process A7 completed I/O; added to ready queue [Q A5 A2 B5 B9 A4 B1 B8 A9 A6 A3 B4 B7 B6 A0 B0 A1 B3 B2 A7]
time 23591ms: Process A8 completed a CPU burst; 4 bursts to go [Q A5 A2 B5 B9 A4 B1 B8 A9 A6 A3 B4 B7 B6 A0 B0 A1 B3 B2 A7]
time 23591ms: Process A8 switching out of CPU; blocking on I/O until time 23666ms [Q A5 A2 B5 B9 A4 B1 B8 A9 A6 A3 B4 B7 B6 A0 B0 A1 B3 B2 A7]
time 23595ms: Process A5 started using the CPU for 60ms burst [Q A2 B5 B9 A4 B1 B8 A9 A6 A3 B4 B7 B6 A0 B0 A1 B3 B2 A7]
time 23655ms: Process A5 completed a CPU burst; 1 burst to go [Q A2 B5 B9 A4 B1 B8 A9 A6 A3 B4 B7 B6 A0 B0 A1 B3 B2 A7]
time 23655ms: Process A5 switching out of CPU; blocking on I/O until time 23763ms [Q A2 B5 B9 A4 B1 B8 A9 A6 A3 B4 B7 B6 A0 B0 A1 B3 B2 A7]
time 23659ms: Process A2 started using the CPU for 92ms burst [Q B5 B9 A4 B1 B8 A9 A6 A3 B4 B7 B6 A0 B0 A1 B3 B2 A7]
time 23666ms: Process A8 completed I/O; added to ready queue [Q B5 B9 A4 B1 B8 A9 A6 A3 B4 B7 B6 A0 B0 A1 B3 B2 A7 A8]
time 23751ms: Process A2 completed a CPU burst; 26 bursts to go [Q B5 B9 A4 B1 B8 A9 A6 A3 B4 B7 B6 A0 B0 A1 B3 B2 A7 A8]
time 23751ms: Process A2 switching out of CPU; blocking on I/O until time 23812ms [Q B5 B9 A4 B1 B8 A9 A6 A3 B4 B7 B6 A0 B0 A1 B3 B2 A7 A8]
time 23755ms: Process B5 started using the CPU for 14ms burst [Q B9 A4 B1 B8 A9 A6 A3 B4 B7 B6 A0 B0 A1 B3 B2 A7 A8]
time 23763ms: Process A5 completed I/O; added to ready queue [Q B9 A4 B1 B8 A9 A6 A3 B4 B7 B6 A0 B0 A1 B3 B2 A7 A8 A5]
time 23769ms: Process B5 completed a CPU burst; 26 bursts to go [Q B9 A4 B1 B8 A9 A6 A3 B4 B7 B6 A0 B0 A1 B3 B2 A7 A8 A5]
time 23769ms: Process B5 switching out of CPU; blocking on I/O until time 24891ms [Q B9 A4 B1 B8 A9 A6 A3 B4 B7 B6 A0 B0 A1 B3 B2 A7 A8 A5]
time 23773ms: Process B9 started using the CPU for 181ms burst [Q A4 B1 B8 A9 A6 A3 B4 B7 B6 A0 B0 A1 B3 B2 A7 A8 A5]
time 23812ms: Process A2 completed I/O; added to ready queue [Q A4 B1 B8 A9 A6 A3 B4 B7 B6 A0 B0 A1 B3 B2 A7 A8 A5 A2]
time 23954ms: Process B9 completed a CPU burst; 7 bursts to go [Q A4 B1 B8 A9 A6 A3 B4 B7 B6 A0 B0 A1 B3 B2 A7 A8 A5 A2]
time 23954ms: Process B9 switching out of CPU; blocking on I/O until time 24148ms [Q A4 B1 B8 A9 A6 A3 B4 B7 B6 A0 B0 A1 B3 B2 A7 A8 A5 A2]
time 23958ms: Process A4 started using the CPU for 276ms burst [Q B1 B8 A9 A6 A3 B4 B7 B6 A0 B0 A1 B3 B2 A7 A8 A5 A2]
time 24148ms: Process B9 completed I/O; added to ready queue [Q B1 B8 A9 A6 A3 B4 B7 B6 A0 B0 A1 B3 B2 A7 A8 A5 A2 B9]
time 24234ms: Process A4 terminated [Q B1 B8 A9 A6 A3 B4 B7 B6 A0 B0 A1 B3 B2 A7 A8 A5 A2 B9]
time 24238ms: Process B1 started using the CPU for 268ms burst [Q B8 A9 A6 A3 B4 B7 B6 A0 B0 A1 B3 B2 A7 A8 A5 A2 B9]
time 24506ms: Process B1 completed a CPU burst; 12 bursts to go [Q B8 A9 A6 A3 B4 B7 B6 A0 B0 A1 B3 B2 A7 A8 A5 A2 B9]
time 24506ms: Process B1 switching out of CPU; blocking on I/O until time 24511ms [Q B8 A9 A6 A3 B4 B7 B6 A0 B0 A1 B3 B2 A7 A8 A5 A2 B9]
time 24510ms: Process B8 started using the CPU for 44ms burst [Q A9 A6 A3 B4 B7 B6 A0 B0 A1 B3 B2 A7 A8 A5 A2 B9]
time 24511ms: Process B1 completed I/O; added to ready queue [Q A9 A6 A3 B4 B7 B6 A0 B0 A1 B3 B2 A7 A8 A5 A2 B9 B1]
time 24554ms: Process B8 completed a CPU burst; 16 bursts to go [Q A9 A6 A3 B4 B7 B6 A0 B0 A1 B3 B2 A7 A8 A5 A2 B9 B1]
time 24554ms: Process B8 switching out of CPU; blocking on I/O until time 27324ms [Q A9 A6 A3 B4 B7 B6 A0 B0 A1 B3 B2 A7 A8 A5 A2 B9 B1]
time 24558ms: Process A9 started using the CPU for 644ms burst [Q A6 A3 B4 B7 B6 A0 B0 A1 B3 B2 A7 A8 A5 A2 B9 B1]
time 24891ms: Process B5 completed I/O; added to ready queue [Q A6 A3 B4 B7 B6 A0 B0 A1 B3 B2 A7 A8 A5 A2 B9 B1 B5]
time 25202ms: Process A9 completed a CPU burst; 27 bursts to go [Q A6 A3 B4 B7 B6 A0 B0 A1 B3 B2 A7 A8 A5 A2 B9 B1 B5]
time 25202ms: Process A9 switching out of CPU; blocking on I/O until time 25255ms [Q A6 A3 B4 B7 B6 A0 B0 A1 B3 B2 A7 A8 A5 A2 B9 B1 B5]
time 25206ms: Process A6 started using the CPU for 180ms burst [Q A3 B4 B7 B6 A0 B0 A1 B3 B2 A7 A8 A5 A2 B9 B1 B5]
time 25255ms: Process A9 completed I/O; added to ready queue [Q A3 B4 B7 B6 A0 B0 A1 B3 B2 A7 A8 A5 A2 B9 B1 B5 A9]
time 25386ms: Process A6 completed a CPU burst; 13 bursts to go [Q A3 B4 B7 B6 A0 B0 A1 B3 B2 A7 A8 A5 A2 B9 B1 B5 A9]
time 25386ms: Process A6 switching out of CPU; blocking on I/O until time 25443ms [Q A3 B4 B7 B6 A0 B0 A1 B3 B2 A7 A8 A5 A2 B9 B1 B5 A9]
time 25390ms: Process A3 started using the CPU for 28ms burst [Q B4 B7 B6 A0 B0 A1 B3 B2 A7 A8 A5 A2 B9 B1 B5 A9]
time 25418ms: Process A3 completed a CPU burst; 22 bursts to go [Q B4 B7 B6 A0 B0 A1 B3 B2 A7 A8 A5 A2 B9 B1 B5 A9]
time 25418ms: Process A3 switching out of CPU; blocking on I/O until time 25658ms [Q B4 B7 B6 A0 B0 A1 B3 B2 A7 A8 A5 A2 B9 B1 B5 A9]
time 25422ms: Process B4 started using the CPU for 39ms burst [Q B7 B6 A0 B0 A1 B3 B2 A7 A8 A5 A2 B9 B1 B5 A9]
time 25443ms: Process A6 completed I/O; added to ready queue [Q B7 B6 A0 B0 A1 B3 B2 A7 A8 A5 A2 B9 B1 B5 A9 A6]
time 25461ms: Process B4 completed a CPU burst; 11 bursts to go [Q B7 B6 A0 B0 A1 B3 B2 A7 A8 A5 A2 B9 B1 B5 A9 A6]
time 25461ms: Process B4 switching out of CPU; blocking on I/O until time 25551ms [Q B7 B6 A0 B0 A1 B3 B2 A7 A8 A5 A2 B9 B1 B5 A9 A6]
time 25465ms: Process B7 started using the CPU for 74ms burst [Q B6 A0 B0 A1 B3 B2 A7 A8 A5 A2 B9 B1 B5 A9 A6]
time 25539ms: Process B7 completed a CPU burst; 22 bursts to go [Q B6 A0 B0 A1 B3 B2 A7 A8 A5 A2 B9 B1 B5 A9 A6]
time 25539ms: Process B7 switching out of CPU; blocking on I/O until time 29253ms [Q B6 A0 B0 A1 B3 B2 A7 A8 A5 A2 B9 B1 B5 A9 A6]
time 25543ms: Process B6 started using the CPU for 10ms burst [Q A0 B0 A1 B3 B2 A7 A8 A5 A2 B9 B1 B5 A9 A6]
time 25551ms: Process B4 completed I/O; added to ready queue [Q A0 B0 A1 B3 B2 A7 A8 A5 A2 B9 B1 B5 A9 A6 B4]
time 25553ms: Process B6 completed a CPU burst; 1 burst to go [Q A0 B0 A1 B3 B2 A7 A8 A5 A2 B9 B1 B5 A9 A6 B4]
time 25553ms: Process B6 switching out of CPU; blocking on I/O until time 26019ms [Q A0 B0 A1 B3 B2 A7 A8 A5 A2 B9 B1 B5 A9 A6 B4]
time 25557ms: Process A0 started using the CPU for 476ms burst [Q B0 A1 B3 B2 A7 A8 A5 A2 B9 B1 B5 A9 A6 B4]
time 25658ms: Process A3 completed I/O; added to ready queue [Q B0 A1 B3 B2 A7 A8 A5 A2 B9 B1 B5 A9 A6 B4 A3]
time 26019ms: Process B6 completed I/O; added to ready queue [Q B0 A1 B3 B2 A7 A8 A5 A2 B9 B1 B5 A9 A6 B4 A3 B6]
time 26033ms: Process A0 completed a CPU burst; 25 bursts to go [Q B0 A1 B3 B2 A7 A8 A5 A2 B9 B1 B5 A9 A6 B4 A3 B6]
time 26033ms: Process A0 switching out of CPU; blocking on I/O until time 26112ms [Q B0 A1 B3 B2 A7 A8 A5 A2 B9 B1 B5 A9 A6 B4 A3 B6]
time 26037ms: Process B0 started using the CPU for 604ms burst [Q A1 B3 B2 A7 A8 A5 A2 B9 B1 B5 A9 A6 B4 A3 B6]
time 26112ms: Process A0 completed I/O; added to ready queue [Q A1 B3 B2 A7 A8 A5 A2 B9 B1 B5 A9 A6 B4 A3 B6 A0]
time 26641ms: Process B0 completed a CPU burst; 14 bursts to go [Q A1 B3 B2 A7 A8 A5 A2 B9 B1 B5 A9 A6 B4 A3 B6 A0]
time 26641ms: Process B0 switching out of CPU; blocking on I/O until time 26680ms [Q A1 B3 B2 A7 A8 A5 A2 B9 B1 B5 A9 A6 B4 A3 B6 A0]
time 26645ms: Process A1 started using the CPU for 100ms burst [Q B3 B2 A7 A8 A5 A2 B9 B1 B5 A9 A6 B4 A3 B6 A0]
time 26680ms: Process B0 completed I/O; added to ready queue [Q B3 B2 A7 A8 A5 A2 B9 B1 B5 A9 A6 B4 A3 B6 A0 B0]
time 26745ms: Process A1 completed a CPU burst; 7 bursts to go [Q B3 B2 A7 A8 A5 A2 B9 B1 B5 A9 A6 B4 A3 B6 A0 B0]
time 26745ms: Process A1 switching out of CPU; blocking on I/O until time 26813ms [Q B3 B2 A7 A8 A5 A2 B9 B1 B5 A9 A6 B4 A3 B6 A0 B0]
time 26749ms: Process B3 started using the CPU for 82ms burst [Q B2 A7 A8 A5 A2 B9 B1 B5 A9 A6 B4 A3 B6 A0 B0]
time 26813ms: Process A1 completed I/O; added to ready queue [Q B2 A7 A8 A5 A2 B9 B1 B5 A9 A6 B4 A3 B6 A0 B0 A1]
time 26831ms: Process B3 completed a CPU burst; 18 bursts to go [Q B2 A7 A8 A5 A2 B9 B1 B5 A9 A6 B4 A3 B6 A0 B0 A1]
time 26831ms: Process B3 switching out of CPU; blocking on I/O until time 27105ms [Q B2 A7 A8 A5 A2 B9 B1 B5 A9 A6 B4 A3 B6 A0 B0 A1]
time 26835ms: Process B2 started using the CPU for 7ms burst [Q A7 A8 A5 A2 B9 B1 B5 A9 A6 B4 A3 B6 A0 B0 A1]
time 26842ms: Process B2 completed a CPU burst; 10 bursts to go [Q A7 A8 A5 A2 B9 B1 B5 A9 A6 B4 A3 B6 A0 B0 A1]
time 26842ms: Process B2 switching out of CPU; blocking on I/O until time 26892ms [Q A7 A8 A5 A2 B9 B1 B5 A9 A6 B4 A3 B6 A0 B0 A1]
time 26846ms: Process A7 started using the CPU for 392ms burst [Q A8 A5 A2 B9 B1 B5 A9 A6 B4 A3 B6 A0 B0 A1]
time 26892ms: Process B2 completed I/O; added to ready queue [Q A8 A5 A2 B9 B1 B5 A9 A6 B4 A3 B6 A0 B0 A1 B2]
time 27105ms: Process B3 completed I/O; added to ready queue [Q A8 A5 A2 B9 B1 B5 A9 A6 B4 A3 B6 A0 B0 A1 B2 B3]
time 27238ms: Process A7 completed a CPU burst; 14 bursts to go [Q A8 A5 A2 B9 B1 B5 A9 A6 B4 A3 B6 A0 B0 A1 B2 B3]
time 27238ms: Process A7 switching out of CPU; blocking on I/O until time 27303ms [Q A8 A5 A2 B9 B1 B5 A9 A6 B4 A3 B6 A0 B0 A1 B2 B3]
time 27242ms: Process A8 started using the CPU for 184ms burst [Q A5 A2 B9 B1 B5 A9 A6 B4 A3 B6 A0 B0 A1 B2 B3]
time 27303ms: Process A7 completed I/O; added to ready queue [Q A5 A2 B9 B1 B5 A9 A6 B4 A3 B6 A0 B0 A1 B2 B3 A7]
time 27324ms: Process B8 completed I/O; added to ready queue [Q A5 A2 B9 B1 B5 A9 A6 B4 A3 B6 A0 B0 A1 B2 B3 A7 B8]
time 27426ms: Process A8 completed a CPU burst; 3 bursts to go [Q A5 A2 B9 B1 B5 A9 A6 B4 A3 B6 A0 B0 A1 B2 B3 A7 B8]
time 27426ms: Process A8 switching out of CPU; blocking on I/O until time 27476ms [Q A5 A2 B9 B1 B5 A9 A6 B4 A3 B6 A0 B0 A1 B2 B3 A7 B8]
time 27430ms: Process A5 started using the CPU for 912ms burst [Q A2 B9 B1 B5 A9 A6 B4 A3 B6 A0 B0 A1 B2 B3 A7 B8]
time 27476ms: Process A8 completed I/O; added to ready queue [Q A2 B9 B1 B5 A9 A6 B4 A3 B6 A0 B0 A1 B2 B3 A7 B8 A8]
time 28342ms: Process A5 terminated [Q A2 B9 B1 B5 A9 A6 B4 A3 B6 A0 B0 A1 B2 B3 A7 B8 A8]
time 28346ms: Process A2 started using the CPU for 136ms burst [Q B9 B1 B5 A9 A6 B4 A3 B6 A0 B0 A1 B2 B3 A7 B8 A8]
time 28482ms: Process A2 completed a CPU burst; 25 bursts to go [Q B9 B1 B5 A9 A6 B4 A3 B6 A0 B0 A1 B2 B3 A7 B8 A8]
time 28482ms: Process A2 switching out of CPU; blocking on I/O until time 28655ms [Q B9 B1 B5 A9 A6 B4 A3 B6 A0 B0 A1 B2 B3 A7 B8 A8]
time 28486ms: Process B9 started using the CPU for 240ms burst [Q B1 B5 A9 A6 B4 A3 B6 A0 B0 A1 B2 B3 A7 B8 A8]
time 28655ms: Process A2 completed I/O; added to ready queue [Q B1 B5 A9 A6 B4 A3 B6 A0 B0 A1 B2 B3 A7 B8 A8 A2]
time 28726ms: Process B9 completed a CPU burst; 6 bursts to go [Q B1 B5 A9 A6 B4 A3 B6 A0 B0 A1 B2 B3 A7 B8 A8 A2]
time 28726ms: Process B9 switching out of CPU; blocking on I/O until time 29112ms [Q B1 B5 A9 A6 B4 A3 B6 A0 B0 A1 B2 B3 A7 B8 A8 A2]
time 28730ms: Process B1 started using the CPU for 64ms burst [Q B5 A9 A6 B4 A3 B6 A0 B0 A1 B2 B3 A7 B8 A8 A2]
time 28794ms: Process B1 completed a CPU burst; 11 bursts to go [Q B5 A9 A6 B4 A3 B6 A0 B0 A1 B2 B3 A7 B8 A8 A2]
time 28794ms: Process B1 switching out of CPU; blocking on I/O until time 29005ms [Q B5 A9 A6 B4 A3 B6 A0 B0 A1 B2 B3 A7 B8 A8 A2]
time 28798ms: Process B5 started using the CPU for 21ms burst [Q A9 A6 B4 A3 B6 A0 B0 A1 B2 B3 A7 B8 A8 A2]
time 28819ms: Process B5 completed a CPU burst; 25 bursts to go [Q A9 A6 B4 A3 B6 A0 B0 A1 B2 B3 A7 B8 A8 A2]
time 28819ms: Process B5 switching out of CPU; blocking on I/O until time 28837ms [Q A9 A6 B4 A3 B6 A0 B0 A1 B2 B3 A7 B8 A8 A2]
time 28823ms: Process A9 started using the CPU for 304ms burst [Q A6 B4 A3 B6 A0 B0 A1 B2 B3 A7 B8 A8 A2]
time 28837ms: Process B5 completed I/O; added to ready queue [Q A6 B4 A3 B6 A0 B0 A1 B2 B3 A7 B8 A8 A2 B5]
time 29005ms: Process B1 completed I/O; added to ready queue [Q A6 B4 A3 B6 A0 B0 A1 B2 B3 A7 B8 A8 A2 B5 B1]
time 29112ms: Process B9 completed I/O; added to ready queue [Q A6 B4 A3 B6 A0 B0 A1 B2 B3 A7 B8 A8 A2 B5 B1 B9]
time 29127ms: Process A9 completed a CPU burst; 26 bursts to go [Q A6 B4 A3 B6 A0 B0 A1 B2 B3 A7 B8 A8 A2 B5 B1 B9]
time 29127ms: Process A9 switching out of CPU; blocking on I/O until time 29283ms [Q A6 B4 A3 B6 A0 B0 A1 B2 B3 A7 B8 A8 A2 B5 B1 B9]
time 29131ms: Process A6 started using the CPU for 264ms burst [Q B4 A3 B6 A0 B0 A1 B2 B3 A7 B8 A8 A2 B5 B1 B9]
time 29253ms: Process B7 completed I/O; added to ready queue [Q B4 A3 B6 A0 B0 A1 B2 B3 A7 B8 A8 A2 B5 B1 B9 B7]
time 29283ms: Process A9 completed I/O; added to ready queue [Q B4 A3 B6 A0 B0 A1 B2 B3 A7 B8 A8 A2 B5 B1 B9 B7 A9]
time 29395ms: Process A6 completed a CPU burst; 12 bursts to go [Q B4 A3 B6 A0 B0 A1 B2 B3 A7 B8 A8 A2 B5 B1 B9 B7 A9]
time 29395ms: Process A6 switching out of CPU; blocking on I/O until time 29498ms [Q B4 A3 B6 A0 B0 A1 B2 B3 A7 B8 A8 A2 B5 B1 B9 B7 A9]
time 29399ms: Process B4 started using the CPU for 205ms burst [Q A3 B6 A0 B0 A1 B2 B3 A7 B8 A8 A2 B5 B1 B9 B7 A9]
time 29498ms: Process A6 completed I/O; added to ready queue [Q A3 B6 A0 B0 A1 B2 B3 A7 B8 A8 A2 B5 B1 B9 B7 A9 A6]
time 29604ms: Process B4 completed a CPU burst; 10 bursts to go [Q A3 B6 A0 B0 A1 B2 B3 A7 B8 A8 A2 B5 B1 B9 B7 A9 A6]
time 29604ms: Process B4 switching out of CPU; blocking on I/O until time 30190ms [Q A3 B6 A0 B0 A1 B2 B3 A7 B8 A8 A2 B5 B1 B9 B7 A9 A6]
time 29608ms: Process A3 started using the CPU for 88ms burst [Q B6 A0 B0 A1 B2 B3 A7 B8 A8 A2 B5 B1 B9 B7 A9 A6]
time 29696ms: Process A3 completed a CPU burst; 21 bursts to go [Q B6 A0 B0 A1 B2 B3 A7 B8 A8 A2 B5 B1 B9 B7 A9 A6]
time 29696ms: Process A3 switching out of CPU; blocking on I/O until time 29761ms [Q B6 A0 B0 A1 B2 B3 A7 B8 A8 A2 B5 B1 B9 B7 A9 A6]
time 29700ms: Process B6 started using the CPU for 46ms burst [Q A0 B0 A1 B2 B3 A7 B8 A8 A2 B5 B1 B9 B7 A9 A6]
time 29746ms: Process B6 terminated [Q A0 B0 A1 B2 B3 A7 B8 A8 A2 B5 B1 B9 B7 A9 A6]
time 29750ms: Process A0 started using the CPU for 28ms burst [Q B0 A1 B2 B3 A7 B8 A8 A2 B5 B1 B9 B7 A9 A6]
time 29761ms: Process A3 completed I/O; added to ready queue [Q B0 A1 B2 B3 A7 B8 A8 A2 B5 B1 B9 B7 A9 A6 A3]
time 29778ms: Process A0 completed a CPU burst; 24 bursts to go [Q B0 A1 B2 B3 A7 B8 A8 A2 B5 B1 B9 B7 A9 A6 A3]
time 29778ms: Process A0 switching out of CPU; blocking on I/O until time 29961ms [Q B0 A1 B2 B3 A7 B8 A8 A2 B5 B1 B9 B7 A9 A6 A3]
time 29782ms: Process B0 started using the CPU for 48ms burst [Q A1 B2 B3 A7 B8 A8 A2 B5 B1 B9 B7 A9 A6 A3]
time 29830ms: Process B0 completed a CPU burst; 13 bursts to go [Q A1 B2 B3 A7 B8 A8 A2 B5 B1 B9 B7 A9 A6 A3]
time 29830ms: Process B0 switching out of CPU; blocking on I/O until time 30127ms [Q A1 B2 B3 A7 B8 A8 A2 B5 B1 B9 B7 A9 A6 A3]
time 29834ms: Process A1 started using the CPU for 256ms burst [Q B2 B3 A7 B8 A8 A2 B5 B1 B9 B7 A9 A6 A3]
time 29961ms: Process A0 completed I/O; added to ready queue [Q B2 B3 A7 B8 A8 A2 B5 B1 B9 B7 A9 A6 A3 A0]
time 30090ms: Process A1 completed a CPU burst; 6 bursts to go [Q B2 B3 A7 B8 A8 A2 B5 B1 B9 B7 A9 A6 A3 A0]
time 30090ms: Process A1 switching out of CPU; blocking on I/O until time 30207ms [Q B2 B3 A7 B8 A8 A2 B5 B1 B9 B7 A9 A6 A3 A0]
time 30094ms: Process B2 started using the CPU for 12ms burst [Q B3 A7 B8 A8 A2 B5 B1 B9 B7 A9 A6 A3 A0]
time 30106ms: Process B2 completed a CPU burst; 9 bursts to go [Q B3 A7 B8 A8 A2 B5 B1 B9 B7 A9 A6 A3 A0]
time 30106ms: Process B2 switching out of CPU; blocking on I/O until time 30460ms [Q B3 A7 B8 A8 A2 B5 B1 B9 B7 A9 A6 A3 A0]
time 30110ms: Process B3 started using the CPU for 125ms burst [Q A7 B8 A8 A2 B5 B1 B9 B7 A9 A6 A3 A0]
time 30127ms: Process B0 completed I/O; added to ready queue [Q A7 B8 A8 A2 B5 B1 B9 B7 A9 A6 A3 A0 B0]
time 30190ms: Process B4 completed I/O; added to ready queue [Q A7 B8 A8 A2 B5 B1 B9 B7 A9 A6 A3 A0 B0 B4]
time 30207ms: Process A1 completed I/O; added to ready queue [Q A7 B8 A8 A2 B5 B1 B9 B7 A9 A6 A3 A0 B0 B4 A1]
time 30235ms: Process B3 completed a CPU burst; 17 bursts to go [Q A7 B8 A8 A2 B5 B1 B9 B7 A9 A6 A3 A0 B0 B4 A1]
time 30235ms: Process B3 switching out of CPU; blocking on I/O until time 31037ms [Q A7 B8 A8 A2 B5 B1 B9 B7 A9 A6 A3 A0 B0 B4 A1]
time 30239ms: Process A7 started using the CPU for 160ms burst [Q B8 A8 A2 B5 B1 B9 B7 A9 A6 A3 A0 B0 B4 A1]
time 30399ms: Process A7 completed a CPU burst; 13 bursts to go [Q B8 A8 A2 B5 B1 B9 B7 A9 A6 A3 A0 B0 B4 A1]
time 30399ms: Process A7 switching out of CPU; blocking on I/O until time 30468ms [Q B8 A8 A2 B5 B1 B9 B7 A9 A6 A3 A0 B0 B4 A1]
time 30403ms: Process B8 started using the CPU for 56ms burst [Q A8 A2 B5 B1 B9 B7 A9 A6 A3 A0 B0 B4 A1]
time 30459ms: Process B8 completed a CPU burst; 15 bursts to go [Q A8 A2 B5 B1 B9 B7 A9 A6 A3 A0 B0 B4 A1]
time 30459ms: Process B8 switching out of CPU; blocking on I/O until time 31685ms [Q A8 A2 B5 B1 B9 B7 A9 A6 A3 A0 B0 B4 A1]
time 30460ms: Process B2 completed I/O; added to ready queue [Q A8 A2 B5 B1 B9 B7 A9 A6 A3 A0 B0 B4 A1 B2]
time 30463ms: Process A8 started using the CPU for 312ms burst [Q A2 B5 B1 B9 B7 A9 A6 A3 A0 B0 B4 A1 B2]
time 30468ms: Process A7 completed I/O; added to ready queue [Q A2 B5 B1 B9 B7 A9 A6 A3 A0 B0 B4 A1 B2 A7]
time 30775ms: Process A8 completed a CPU burst; 2 bursts to go [Q A2 B5 B1 B9 B7 A9 A6 A3 A0 B0 B4 A1 B2 A7]
time 30775ms: Process A8 switching out of CPU; blocking on I/O until time 30972ms [Q A2 B5 B1 B9 B7 A9 A6 A3 A0 B0 B4 A1 B2 A7]
time 30779ms: Process A2 started using the CPU for 236ms burst [Q B5 B1 B9 B7 A9 A6 A3 A0 B0 B4 A1 B2 A7]
time 30972ms: Process A8 completed I/O; added to ready queue [Q B5 B1 B9 B7 A9 A6 A3 A0 B0 B4 A1 B2 A7 A8]
time 31015ms: Process A2 completed a CPU burst; 24 bursts to go [Q B5 B1 B9 B7 A9 A6 A3 A0 B0 B4 A1 B2 A7 A8]
time 31015ms: Process A2 switching out of CPU; blocking on I/O until time 31101ms [Q B5 B1 B9 B7 A9 A6 A3 A0 B0 B4 A1 B2 A7 A8]
time 31019ms: Process B5 started using the CPU for 24ms burst [Q B1 B9 B7 A9 A6 A3 A0 B0 B4 A1 B2 A7 A8]
time 31037ms: Process B3 completed I/O; added to ready queue [Q B1 B9 B7 A9 A6 A3 A0 B0 B4 A1 B2 A7 A8 B3]
time 31043ms: Process B5 completed a CPU burst; 24 bursts to go [Q B1 B9 B7 A9 A6 A3 A0 B0 B4 A1 B2 A7 A8 B3]
time 31043ms: Process B5 switching out of CPU; blocking on I/O until time 31197ms [Q B1 B9 B7 A9 A6 A3 A0 B0 B4 A1 B2 A7 A8 B3]
time 31047ms: Process B1 started using the CPU for 636ms burst [Q B9 B7 A9 A6 A3 A0 B0 B4 A1 B2 A7 A8 B3]
time 31101ms: Process A2 completed I/O; added to ready queue [Q B9 B7 A9 A6 A3 A0 B0 B4 A1 B2 A7 A8 B3 A2]
time 31197ms: Process B5 completed I/O; added to ready queue [Q B9 B7 A9 A6 A3 A0 B0 B4 A1 B2 A7 A8 B3 A2 B5]
time 31683ms: Process B1 completed a CPU burst; 10 bursts to go [Q B9 B7 A9 A6 A3 A0 B0 B4 A1 B2 A7 A8 B3 A2 B5]
time 31683ms: Process B1 switching out of CPU; blocking on I/O until time 31901ms [Q B9 B7 A9 A6 A3 A0 B0 B4 A1 B2 A7 A8 B3 A2 B5]
time 31685ms: Process B8 completed I/O; added to ready queue [Q B9 B7 A9 A6 A3 A0 B0 B4 A1 B2 A7 A8 B3 A2 B5 B8]
time 31687ms: Process B9 started using the CPU for 23ms burst [Q B7 A9 A6 A3 A0 B0 B4 A1 B2 A7 A8 B3 A2 B5 B8]
time 31710ms: Process B9 completed a CPU burst; 5 bursts to go [Q B7 A9 A6 A3 A0 B0 B4 A1 B2 A7 A8 B3 A2 B5 B8]
time 31710ms: Process B9 switching out of CPU; blocking on I/O until time 31840ms [Q B7 A9 A6 A3 A0 B0 B4 A1 B2 A7 A8 B3 A2 B5 B8]
time 31714ms: Process B7 started using the CPU for 133ms burst [Q A9 A6 A3 A0 B0 B4 A1 B2 A7 A8 B3 A2 B5 B8]
time 31840ms: Process B9 completed I/O; added to ready queue [Q A9 A6 A3 A0 B0 B4 A1 B2 A7 A8 B3 A2 B5 B8 B9]
time 31847ms: Process B7 completed a CPU burst; 21 bursts to go [Q A9 A6 A3 A0 B0 B4 A1 B2 A7 A8 B3 A2 B5 B8 B9]
time 31847ms: Process B7 switching out of CPU; blocking on I/O until time 33121ms [Q A9 A6 A3 A0 B0 B4 A1 B2 A7 A8 B3 A2 B5 B8 B9]
time 31851ms: Process A9 started using the CPU for 400ms burst [Q A6 A3 A0 B0 B4 A1 B2 A7 A8 B3 A2 B5 B8 B9]
time 31901ms: Process B1 completed I/O; added to ready queue [Q A6 A3 A0 B0 B4 A1 B2 A7 A8 B3 A2 B5 B8 B9 B1]
time 32251ms: Process A9 completed a CPU burst; 25 bursts to go [Q A6 A3 A0 B0 B4 A1 B2 A7 A8 B3 A2 B5 B8 B9 B1]
time 32251ms: Process A9 switching out of CPU; blocking on I/O until time 32358ms [Q A6 A3 A0 B0 B4 A1 B2 A7 A8 B3 A2 B5 B8 B9 B1]
time 32255ms: Process A6 started using the CPU for 588ms burst [Q A3 A0 B0 B4 A1 B2 A7 A8 B3 A2 B5 B8 B9 B1]
time 32358ms: Process A9 completed I/O; added to ready queue [Q A3 A0 B0 B4 A1 B2 A7 A8 B3 A2 B5 B8 B9 B1 A9]
time 32843ms: Process A6 completed a CPU burst; 11 bursts to go [Q A3 A0 B0 B4 A1 B2 A7 A8 B3 A2 B5 B8 B9 B1 A9]
time 32843ms: Process A6 switching out of CPU; blocking on I/O until time 32892ms [Q A3 A0 B0 B4 A1 B2 A7 A8 B3 A2 B5 B8 B9 B1 A9]
time 32847ms: Process A3 started using the CPU for 116ms burst [Q A0 B0 B4 A1 B2 A7 A8 B3 A2 B5 B8 B9 B1 A9]
time 32892ms: Process A6 completed I/O; added to ready queue [Q A0 B0 B4 A1 B2 A7 A8 B3 A2 B5 B8 B9 B1 A9 A6]
time 32963ms: Process A3 completed a CPU burst; 20 bursts to go [Q A0 B0 B4 A1 B2 A7 A8 B3 A2 B5 B8 B9 B1 A9 A6]
time 32963ms: Process A3 switching out of CPU; blocking on I/O until time 33019ms [Q A0 B0 B4 A1 B2 A7 A8 B3 A2 B5 B8 B9 B1 A9 A6]
time 32967ms: Process A0 started using the CPU for 184ms burst [Q B0 B4 A1 B2 A7 A8 B3 A2 B5 B8 B9 B1 A9 A6]
time 33019ms: Process A3 completed I/O; added to ready queue [Q B0 B4 A1 B2 A7 A8 B3 A2 B5 B8 B9 B1 A9 A6 A3]
time 33121ms: Process B7 completed I/O; added to ready queue [Q B0 B4 A1 B2 A7 A8 B3 A2 B5 B8 B9 B1 A9 A6 A3 B7]
time 33151ms: Process A0 completed a CPU burst; 23 bursts to go [Q B0 B4 A1 B2 A7 A8 B3 A2 B5 B8 B9 B1 A9 A6 A3 B7]
time 33151ms: Process A0 switching out of CPU; blocking on I/O until time 33723ms [Q B0 B4 A1 B2 A7 A8 B3 A2 B5 B8 B9 B1 A9 A6 A3 B7]
time 33155ms: Process B0 started using the CPU for 224ms burst [Q B4 A1 B2 A7 A8 B3 A2 B5 B8 B9 B1 A9 A6 A3 B7]
time 33379ms: Process B0 completed a CPU burst; 12 bursts to go [Q B4 A1 B2 A7 A8 B3 A2 B5 B8 B9 B1 A9 A6 A3 B7]
time 33379ms: Process B0 switching out of CPU; blocking on I/O until time 33477ms [Q B4 A1 B2 A7 A8 B3 A2 B5 B8 B9 B1 A9 A6 A3 B7]
time 33383ms: Process B4 started using the CPU for 47ms burst [Q A1 B2 A7 A8 B3 A2 B5 B8 B9 B1 A9 A6 A3 B7]
time 33430ms: Process B4 completed a CPU burst; 9 bursts to go [Q A1 B2 A7 A8 B3 A2 B5 B8 B9 B1 A9 A6 A3 B7]
time 33430ms: Process B4 switching out of CPU; blocking on I/O until time 33888ms [Q A1 B2 A7 A8 B3 A2 B5 B8 B9 B1 A9 A6 A3 B7]
time 33434ms: Process A1 started using the CPU for 1684ms burst [Q B2 A7 A8 B3 A2 B5 B8 B9 B1 A9 A6 A3 B7]
time 33477ms: Process B0 completed I/O; added to ready queue [Q B2 A7 A8 B3 A2 B5 B8 B9 B1 A9 A6 A3 B7 B0]
time 33723ms: Process A0 completed I/O; added to ready queue [Q B2 A7 A8 B3 A2 B5 B8 B9 B1 A9 A6 A3 B7 B0 A0]
time 33888ms: Process B4 completed I/O; added to ready queue [Q B2 A7 A8 B3 A2 B5 B8 B9 B1 A9 A6 A3 B7 B0 A0 B4]
time 35118ms: Process A1 completed a CPU burst; 5 bursts to go [Q B2 A7 A8 B3 A2 B5 B8 B9 B1 A9 A6 A3 B7 B0 A0 B4]
time 35118ms: Process A1 switching out of CPU; blocking on I/O until time 35182ms [Q B2 A7 A8 B3 A2 B5 B8 B9 B1 A9 A6 A3 B7 B0 A0 B4]
time 35122ms: Process B2 started using the CPU for 142ms burst [Q A7 A8 B3 A2 B5 B8 B9 B1 A9 A6 A3 B7 B0 A0 B4]
time 35182ms: Process A1 completed I/O; added to ready queue [Q A7 A8 B3 A2 B5 B8 B9 B1 A9 A6 A3 B7 B0 A0 B4 A1]
time 35264ms: Process B2 completed a CPU burst; 8 bursts to go [Q A7 A8 B3 A2 B5 B8 B9 B1 A9 A6 A3 B7 B0 A0 B4 A1]
time 35264ms: Process B2 switching out of CPU; blocking on I/O until time 35298ms [Q A7 A8 B3 A2 B5 B8 B9 B1 A9 A6 A3 B7 B0 A0 B4 A1]
time 35268ms: Process A7 started using the CPU for 140ms burst [Q A8 B3 A2 B5 B8 B9 B1 A9 A6 A3 B7 B0 A0 B4 A1]
time 35298ms: Process B2 completed I/O; added to ready queue [Q A8 B3 A2 B5 B8 B9 B1 A9 A6 A3 B7 B0 A0 B4 A1 B2]
time 35408ms: Process A7 completed a CPU burst; 12 bursts to go [Q A8 B3 A2 B5 B8 B9 B1 A9 A6 A3 B7 B0 A0 B4 A1 B2]
time 35408ms: Process A7 switching out of CPU; blocking on I/O until time 35557ms [Q A8 B3 A2 B5 B8 B9 B1 A9 A6 A3 B7 B0 A0 B4 A1 B2]
time 35412ms: Process A8 started using the CPU for 2620ms burst [Q B3 A2 B5 B8 B9 B1 A9 A6 A3 B7 B0 A0 B4 A1 B2]
time 35557ms: Process A7 completed I/O; added to ready queue [Q B3 A2 B5 B8 B9 B1 A9 A6 A3 B7 B0 A0 B4 A1 B2 A7]
time 38032ms: Process A8 completed a CPU burst; 1 burst to go [Q B3 A2 B5 B8 B9 B1 A9 A6 A3 B7 B0 A0 B4 A1 B2 A7]
time 38032ms: Process A8 switching out of CPU; blocking on I/O until time 38054ms [Q B3 A2 B5 B8 B9 B1 A9 A6 A3 B7 B0 A0 B4 A1 B2 A7]
time 38036ms: Process B3 started using the CPU for 31ms burst [Q A2 B5 B8 B9 B1 A9 A6 A3 B7 B0 A0 B4 A1 B2 A7]
time 38054ms: Process A8 completed I/O; added to ready queue [Q A2 B5 B8 B9 B1 A9 A6 A3 B7 B0 A0 B4 A1 B2 A7 A8]
time 38067ms: Process B3 completed a CPU burst; 16 bursts to go [Q A2 B5 B8 B9 B1 A9 A6 A3 B7 B0 A0 B4 A1 B2 A7 A8]
time 38067ms: Process B3 switching out of CPU; blocking on I/O until time 41221ms [Q A2 B5 B8 B9 B1 A9 A6 A3 B7 B0 A0 B4 A1 B2 A7 A8]
time 38071ms: Process A2 started using the CPU for 112ms burst [Q B5 B8 B9 B1 A9 A6 A3 B7 B0 A0 B4 A1 B2 A7 A8]
time 38183ms: Process A2 completed a CPU burst; 23 bursts to go [Q B5 B8 B9 B1 A9 A6 A3 B7 B0 A0 B4 A1 B2 A7 A8]
time 38183ms: Process A2 switching out of CPU; blocking on I/O until time 38307ms [Q B5 B8 B9 B1 A9 A6 A3 B7 B0 A0 B4 A1 B2 A7 A8]
time 38187ms: Process B5 started using the CPU for 120ms burst [Q B8 B9 B1 A9 A6 A3 B7 B0 A0 B4 A1 B2 A7 A8]
time 38307ms: Process B5 completed a CPU burst; 23 bursts to go [Q B8 B9 B1 A9 A6 A3 B7 B0 A0 B4 A1 B2 A7 A8]
time 38307ms: Process B5 switching out of CPU; blocking on I/O until time 38949ms [Q B8 B9 B1 A9 A6 A3 B7 B0 A0 B4 A1 B2 A7 A8]
time 38307ms: Process A2 completed I/O; added to ready queue [Q B8 B9 B1 A9 A6 A3 B7 B0 A0 B4 A1 B2 A7 A8 A2]
time 38311ms: Process B8 started using the CPU for 13ms burst [Q B9 B1 A9 A6 A3 B7 B0 A0 B4 A1 B2 A7 A8 A2]
time 38324ms: Process B8 completed a CPU burst; 14 bursts to go [Q B9 B1 A9 A6 A3 B7 B0 A0 B4 A1 B2 A7 A8 A2]
time 38324ms: Process B8 switching out of CPU; blocking on I/O until time 38766ms [Q B9 B1 A9 A6 A3 B7 B0 A0 B4 A1 B2 A7 A8 A2]
time 38328ms: Process B9 started using the CPU for 148ms burst [Q B1 A9 A6 A3 B7 B0 A0 B4 A1 B2 A7 A8 A2]
time 38476ms: Process B9 completed a CPU burst; 4 bursts to go [Q B1 A9 A6 A3 B7 B0 A0 B4 A1 B2 A7 A8 A2]
time 38476ms: Process B9 switching out of CPU; blocking on I/O until time 38966ms [Q B1 A9 A6 A3 B7 B0 A0 B4 A1 B2 A7 A8 A2]
time 38480ms: Process B1 started using the CPU for 620ms burst [Q A9 A6 A3 B7 B0 A0 B4 A1 B2 A7 A8 A2]
time 38766ms: Process B8 completed I/O; added to ready queue [Q A9 A6 A3 B7 B0 A0 B4 A1 B2 A7 A8 A2 B8]
time 38949ms: Process B5 completed I/O; added to ready queue [Q A9 A6 A3 B7 B0 A0 B4 A1 B2 A7 A8 A2 B8 B5]
time 38966ms: Process B9 completed I/O; added to ready queue [Q A9 A6 A3 B7 B0 A0 B4 A1 B2 A7 A8 A2 B8 B5 B9]
time 39100ms: Process B1 completed a CPU burst; 9 bursts to go [Q A9 A6 A3 B7 B0 A0 B4 A1 B2 A7 A8 A2 B8 B5 B9]
time 39100ms: Process B1 switching out of CPU; blocking on I/O until time 39284ms [Q A9 A6 A3 B7 B0 A0 B4 A1 B2 A7 A8 A2 B8 B5 B9]
time 39104ms: Process A9 started using the CPU for 72ms burst [Q A6 A3 B7 B0 A0 B4 A1 B2 A7 A8 A2 B8 B5 B9]
time 39176ms: Process A9 completed a CPU burst; 24 bursts to go [Q A6 A3 B7 B0 A0 B4 A1 B2 A7 A8 A2 B8 B5 B9]
time 39176ms: Process A9 switching out of CPU; blocking on I/O until time 39217ms [Q A6 A3 B7 B0 A0 B4 A1 B2 A7 A8 A2 B8 B5 B9]
time 39180ms: Process A6 started using the CPU for 84ms burst [Q A3 B7 B0 A0 B4 A1 B2 A7 A8 A2 B8 B5 B9]
time 39217ms: Process A9 completed I/O; added to ready queue [Q A3 B7 B0 A0 B4 A1 B2 A7 A8 A2 B8 B5 B9 A9]
time 39264ms: Process A6 completed a CPU burst; 10 bursts to go [Q A3 B7 B0 A0 B4 A1 B2 A7 A8 A2 B8 B5 B9 A9]
time 39264ms: Process A6 switching out of CPU; blocking on I/O until time 39283ms [Q A3 B7 B0 A0 B4 A1 B2 A7 A8 A2 B8 B5 B9 A9]
time 39268ms: Process A3 started using the CPU for 580ms burst [Q B7 B0 A0 B4 A1 B2 A7 A8 A2 B8 B5 B9 A9]
time 39283ms: Process A6 completed I/O; added to ready queue [Q B7 B0 A0 B4 A1 B2 A7 A8 A2 B8 B5 B9 A9 A6]
time 39284ms: Process B1 completed I/O; added to ready queue [Q B7 B0 A0 B4 A1 B2 A7 A8 A2 B8 B5 B9 A9 A6 B1]
time 39848ms: Process A3 completed a CPU burst; 19 bursts to go [Q B7 B0 A0 B4 A1 B2 A7 A8 A2 B8 B5 B9 A9 A6 B1]
time 39848ms: Process A3 switching out of CPU; blocking on I/O until time 39855ms [Q B7 B0 A0 B4 A1 B2 A7 A8 A2 B8 B5 B9 A9 A6 B1]
time 39852ms: Process B7 started using the CPU for 24ms burst [Q B0 A0 B4 A1 B2 A7 A8 A2 B8 B5 B9 A9 A6 B1]
time 39855ms: Process A3 completed I/O; added to ready queue [Q B0 A0 B4 A1 B2 A7 A8 A2 B8 B5 B9 A9 A6 B1 A3]
time 39876ms: Process B7 completed a CPU burst; 20 bursts to go [Q B0 A0 B4 A1 B2 A7 A8 A2 B8 B5 B9 A9 A6 B1 A3]
time 39876ms: Process B7 switching out of CPU; blocking on I/O until time 42142ms [Q B0 A0 B4 A1 B2 A7 A8 A2 B8 B5 B9 A9 A6 B1 A3]
time 39880ms: Process B0 started using the CPU for 136ms burst [Q A0 B4 A1 B2 A7 A8 A2 B8 B5 B9 A9 A6 B1 A3]
time 40016ms: Process B0 completed a CPU burst; 11 bursts to go [Q A0 B4 A1 B2 A7 A8 A2 B8 B5 B9 A9 A6 B1 A3]
time 40016ms: Process B0 switching out of CPU; blocking on I/O until time 40024ms [Q A0 B4 A1 B2 A7 A8 A2 B8 B5 B9 A9 A6 B1 A3]
time 40020ms: Process A0 started using the CPU for 268ms burst [Q B4 A1 B2 A7 A8 A2 B8 B5 B9 A9 A6 B1 A3]
time 40024ms: Process B0 completed I/O; added to ready queue [Q B4 A1 B2 A7 A8 A2 B8 B5 B9 A9 A6 B1 A3 B0]
time 40288ms: Process A0 completed a CPU burst; 22 bursts to go [Q B4 A1 B2 A7 A8 A2 B8 B5 B9 A9 A6 B1 A3 B0]
time 40288ms: Process A0 switching out of CPU; blocking on I/O until time 40342ms [Q B4 A1 B2 A7 A8 A2 B8 B5 B9 A9 A6 B1 A3 B0]
time 40292ms: Process B4 started using the CPU for 66ms burst [Q A1 B2 A7 A8 A2 B8 B5 B9 A9 A6 B1 A3 B0]
time 40342ms: Process A0 completed I/O; added to ready queue [Q A1 B2 A7 A8 A2 B8 B5 B9 A9 A6 B1 A3 B0 A0]
time 40358ms: Process B4 completed a CPU burst; 8 bursts to go [Q A1 B2 A7 A8 A2 B8 B5 B9 A9 A6 B1 A3 B0 A0]
time 40358ms: Process B4 switching out of CPU; blocking on I/O until time 43752ms [Q A1 B2 A7 A8 A2 B8 B5 B9 A9 A6 B1 A3 B0 A0]
time 40362ms: Process A1 started using the CPU for 600ms burst [Q B2 A7 A8 A2 B8 B5 B9 A9 A6 B1 A3 B0 A0]
time 40962ms: Process A1 completed a CPU burst; 4 bursts to go [Q B2 A7 A8 A2 B8 B5 B9 A9 A6 B1 A3 B0 A0]
time 40962ms: Process A1 switching out of CPU; blocking on I/O until time 41065ms [Q B2 A7 A8 A2 B8 B5 B9 A9 A6 B1 A3 B0 A0]
time 40966ms: Process B2 started using the CPU for 81ms burst [Q A7 A8 A2 B8 B5 B9 A9 A6 B1 A3 B0 A0]
time 41047ms: Process B2 completed a CPU burst; 7 bursts to go [Q A7 A8 A2 B8 B5 B9 A9 A6 B1 A3 B0 A0]
time 41047ms: Process B2 switching out of CPU; blocking on I/O until time 41393ms [Q A7 A8 A2 B8 B5 B9 A9 A6 B1 A3 B0 A0]
time 41051ms: Process A7 started using the CPU for 524ms burst [Q A8 A2 B8 B5 B9 A9 A6 B1 A3 B0 A0]
time 41065ms: Process A1 completed I/O; added to ready queue [Q A8 A2 B8 B5 B9 A9 A6 B1 A3 B0 A0 A1]
time 41221ms: Process B3 completed I/O; added to ready queue [Q A8 A2 B8 B5 B9 A9 A6 B1 A3 B0 A0 A1 B3]
time 41393ms: Process B2 completed I/O; added to ready queue [Q A8 A2 B8 B5 B9 A9 A6 B1 A3 B0 A0 A1 B3 B2]
time 41575ms: Process A7 completed a CPU burst; 11 bursts to go [Q A8 A2 B8 B5 B9 A9 A6 B1 A3 B0 A0 A1 B3 B2]
time 41575ms: Process A7 switching out of CPU; blocking on I/O until time 41649ms [Q A8 A2 B8 B5 B9 A9 A6 B1 A3 B0 A0 A1 B3 B2]
time 41579ms: Process A8 started using the CPU for 112ms burst [Q A2 B8 B5 B9 A9 A6 B1 A3 B0 A0 A1 B3 B2]
time 41649ms: Process A7 completed I/O; added to ready queue [Q A2 B8 B5 B9 A9 A6 B1 A3 B0 A0 A1 B3 B2 A7]
time 41691ms: Process A8 terminated [Q A2 B8 B5 B9 A9 A6 B1 A3 B0 A0 A1 B3 B2 A7]
time 41695ms: Process A2 started using the CPU for 284ms burst [Q B8 B5 B9 A9 A6 B1 A3 B0 A0 A1 B3 B2 A7]
time 41979ms: Process A2 completed a CPU burst; 22 bursts to go [Q B8 B5 B9 A9 A6 B1 A3 B0 A0 A1 B3 B2 A7]
time 41979ms: Process A2 switching out of CPU; blocking on I/O until time 42006ms [Q B8 B5 B9 A9 A6 B1 A3 B0 A0 A1 B3 B2 A7]
time 41983ms: Process B8 started using the CPU for 14ms burst [Q B5 B9 A9 A6 B1 A3 B0 A0 A1 B3 B2 A7]
time 41997ms: Process B8 completed a CPU burst; 13 bursts to go [Q B5 B9 A9 A6 B1 A3 B0 A0 A1 B3 B2 A7]
time 41997ms: Process B8 switching out of CPU; blocking on I/O until time 42191ms [Q B5 B9 A9 A6 B1 A3 B0 A0 A1 B3 B2 A7]
time 42001ms: Process B5 started using the CPU for 72ms burst [Q B9 A9 A6 B1 A3 B0 A0 A1 B3 B2 A7]
time 42006ms: Process A2 completed I/O; added to ready queue [Q B9 A9 A6 B1 A3 B0 A0 A1 B3 B2 A7 A2]
time 42073ms: Process B5 completed a CPU burst; 22 bursts to go [Q B9 A9 A6 B1 A3 B0 A0 A1 B3 B2 A7 A2]
time 42073ms: Process B5 switching out of CPU; blocking on I/O until time 42387ms [Q B9 A9 A6 B1 A3 B0 A0 A1 B3 B2 A7 A2]
time 42077ms: Process B9 started using the CPU for 159ms burst [Q A9 A6 B1 A3 B0 A0 A1 B3 B2 A7 A2]
time 42142ms: Process B7 completed I/O; added to ready queue [Q A9 A6 B1 A3 B0 A0 A1 B3 B2 A7 A2 B7]
time 42191ms: Process B8 completed I/O; added to ready queue [Q A9 A6 B1 A3 B0 A0 A1 B3 B2 A7 A2 B7 B8]
time 42236ms: Process B9 completed a CPU burst; 3 bursts to go [Q A9 A6 B1 A3 B0 A0 A1 B3 B2 A7 A2 B7 B8]
time 42236ms: Process B9 switching out of CPU; blocking on I/O until time 43022ms [Q A9 A6 B1 A3 B0 A0 A1 B3 B2 A7 A2 B7 B8]
time 42240ms: Process A9 started using the CPU for 316ms burst [Q A6 B1 A3 B0 A0 A1 B3 B2 A7 A2 B7 B8]
time 42387ms: Process B5 completed I/O; added to ready queue [Q A6 B1 A3 B0 A0 A1 B3 B2 A7 A2 B7 B8 B5]
time 42556ms: Process A9 completed a CPU burst; 23 bursts to go [Q A6 B1 A3 B0 A0 A1 B3 B2 A7 A2 B7 B8 B5]
time 42556ms: Process A9 switching out of CPU; blocking on I/O until time 42598ms [Q A6 B1 A3 B0 A0 A1 B3 B2 A7 A2 B7 B8 B5]
time 42560ms: Process A6 started using the CPU for 1312ms burst [Q B1 A3 B0 A0 A1 B3 B2 A7 A2 B7 B8 B5]
time 42598ms: Process A9 completed I/O; added to ready queue [Q B1 A3 B0 A0 A1 B3 B2 A7 A2 B7 B8 B5 A9]
time 43022ms: Process B9 completed I/O; added to ready queue [Q B1 A3 B0 A0 A1 B3 B2 A7 A2 B7 B8 B5 A9 B9]
time 43752ms: Process B4 completed I/O; added to ready queue [Q B1 A3 B0 A0 A1 B3 B2 A7 A2 B7 B8 B5 A9 B9 B4]
time 43872ms: Process A6 completed a CPU burst; 9 bursts to go [Q B1 A3 B0 A0 A1 B3 B2 A7 A2 B7 B8 B5 A9 B9 B4]
time 43872ms: Process A6 switching out of CPU; blocking on I/O until time 43940ms [Q B1 A3 B0 A0 A1 B3 B2 A7 A2 B7 B8 B5 A9 B9 B4]
time 43876ms: Process B1 started using the CPU for 2136ms burst [Q A3 B0 A0 A1 B3 B2 A7 A2 B7 B8 B5 A9 B9 B4]
time 43940ms: Process A6 completed I/O; added to ready queue [Q A3 B0 A0 A1 B3 B2 A7 A2 B7 B8 B5 A9 B9 B4 A6]
time 46012ms: Process B1 completed a CPU burst; 8 bursts to go [Q A3 B0 A0 A1 B3 B2 A7 A2 B7 B8 B5 A9 B9 B4 A6]
time 46012ms: Process B1 switching out of CPU; blocking on I/O until time 46193ms [Q A3 B0 A0 A1 B3 B2 A7 A2 B7 B8 B5 A9 B9 B4 A6]
time 46016ms: Process A3 started using the CPU for 72ms burst [Q B0 A0 A1 B3 B2 A7 A2 B7 B8 B5 A9 B9 B4 A6]
time 46088ms: Process A3 completed a CPU burst; 18 bursts to go [Q B0 A0 A1 B3 B2 A7 A2 B7 B8 B5 A9 B9 B4 A6]
time 46088ms: Process A3 switching out of CPU; blocking on I/O until time 46167ms [Q B0 A0 A1 B3 B2 A7 A2 B7 B8 B5 A9 B9 B4 A6]
time 46092ms: Process B0 started using the CPU for 948ms burst [Q A0 A1 B3 B2 A7 A2 B7 B8 B5 A9 B9 B4 A6]
time 46167ms: Process A3 completed I/O; added to ready queue [Q A0 A1 B3 B2 A7 A2 B7 B8 B5 A9 B9 B4 A6 A3]
time 46193ms: Process B1 completed I/O; added to ready queue [Q A0 A1 B3 B2 A7 A2 B7 B8 B5 A9 B9 B4 A6 A3 B1]
time 47040ms: Process B0 completed a CPU burst; 10 bursts to go [Q A0 A1 B3 B2 A7 A2 B7 B8 B5 A9 B9 B4 A6 A3 B1]
time 47040ms: Process B0 switching out of CPU; blocking on I/O until time 47044ms [Q A0 A1 B3 B2 A7 A2 B7 B8 B5 A9 B9 B4 A6 A3 B1]
time 47044ms: Process A0 started using the CPU for 412ms burst [Q A1 B3 B2 A7 A2 B7 B8 B5 A9 B9 B4 A6 A3 B1]
time 47044ms: Process B0 completed I/O; added to ready queue [Q A1 B3 B2 A7 A2 B7 B8 B5 A9 B9 B4 A6 A3 B1 B0]
time 47456ms: Process A0 completed a CPU burst; 21 bursts to go [Q A1 B3 B2 A7 A2 B7 B8 B5 A9 B9 B4 A6 A3 B1 B0]
time 47456ms: Process A0 switching out of CPU; blocking on I/O until time 47541ms [Q A1 B3 B2 A7 A2 B7 B8 B5 A9 B9 B4 A6 A3 B1 B0]
time 47460ms: Process A1 started using the CPU for 180ms burst [Q B3 B2 A7 A2 B7 B8 B5 A9 B9 B4 A6 A3 B1 B0]
time 47541ms: Process A0 completed I/O; added to ready queue [Q B3 B2 A7 A2 B7 B8 B5 A9 B9 B4 A6 A3 B1 B0 A0]
time 47640ms: Process A1 completed a CPU burst; 3 bursts to go [Q B3 B2 A7 A2 B7 B8 B5 A9 B9 B4 A6 A3 B1 B0 A0]
time 47640ms: Process A1 switching out of CPU; blocking on I/O until time 47709ms [Q B3 B2 A7 A2 B7 B8 B5 A9 B9 B4 A6 A3 B1 B0 A0]
time 47644ms: Process B3 started using the CPU for 61ms burst [Q B2 A7 A2 B7 B8 B5 A9 B9 B4 A6 A3 B1 B0 A0]
time 47705ms: Process B3 completed a CPU burst; 15 bursts to go [Q B2 A7 A2 B7 B8 B5 A9 B9 B4 A6 A3 B1 B0 A0]
time 47705ms: Process B3 switching out of CPU; blocking on I/O until time 50675ms [Q B2 A7 A2 B7 B8 B5 A9 B9 B4 A6 A3 B1 B0 A0]
time 47709ms: Process B2 started using the CPU for 28ms burst [Q A7 A2 B7 B8 B5 A9 B9 B4 A6 A3 B1 B0 A0]
time 47709ms: Process A1 completed I/O; added to ready queue [Q A7 A2 B7 B8 B5 A9 B9 B4 A6 A3 B1 B0 A0 A1]
time 47737ms: Process B2 completed a CPU burst; 6 bursts to go [Q A7 A2 B7 B8 B5 A9 B9 B4 A6 A3 B1 B0 A0 A1]
time 47737ms: Process B2 switching out of CPU; blocking on I/O until time 48339ms [Q A7 A2 B7 B8 B5 A9 B9 B4 A6 A3 B1 B0 A0 A1]
time 47741ms: Process A7 started using the CPU for 484ms burst [Q A2 B7 B8 B5 A9 B9 B4 A6 A3 B1 B0 A0 A1]
time 48225ms: Process A7 completed a CPU burst; 10 bursts to go [Q A2 B7 B8 B5 A9 B9 B4 A6 A3 B1 B0 A0 A1]
time 48225ms: Process A7 switching out of CPU; blocking on I/O until time 48264ms [Q A2 B7 B8 B5 A9 B9 B4 A6 A3 B1 B0 A0 A1]
time 48229ms: Process A2 started using the CPU for 524ms burst [Q B7 B8 B5 A9 B9 B4 A6 A3 B1 B0 A0 A1]
time 48264ms: Process A7 completed I/O; added to ready queue [Q B7 B8 B5 A9 B9 B4 A6 A3 B1 B0 A0 A1 A7]
time 48339ms: Process B2 completed I/O; added to ready queue [Q B7 B8 B5 A9 B9 B4 A6 A3 B1 B0 A0 A1 A7 B2]
time 48753ms: Process A2 completed a CPU burst; 21 bursts to go [Q B7 B8 B5 A9 B9 B4 A6 A3 B1 B0 A0 A1 A7 B2]
time 48753ms: Process A2 switching out of CPU; blocking on I/O until time 48941ms [Q B7 B8 B5 A9 B9 B4 A6 A3 B1 B0 A0 A1 A7 B2]
time 48757ms: Process B7 started using the CPU for 11ms burst [Q B8 B5 A9 B9 B4 A6 A3 B1 B0 A0 A1 A7 B2]
time 48768ms: Process B7 completed a CPU burst; 19 bursts to go [Q B8 B5 A9 B9 B4 A6 A3 B1 B0 A0 A1 A7 B2]
time 48768ms: Process B7 switching out of CPU; blocking on I/O until time 48890ms [Q B8 B5 A9 B9 B4 A6 A3 B1 B0 A0 A1 A7 B2]
time 48772ms: Process B8 started using the CPU for 32ms burst [Q B5 A9 B9 B4 A6 A3 B1 B0 A0 A1 A7 B2]
time 48804ms: Process B8 completed a CPU burst; 12 bursts to go [Q B5 A9 B9 B4 A6 A3 B1 B0 A0 A1 A7 B2]
time 48804ms: Process B8 switching out of CPU; blocking on I/O until time 49230ms [Q B5 A9 B9 B4 A6 A3 B1 B0 A0 A1 A7 B2]
time 48808ms: Process B5 started using the CPU for 194ms burst [Q A9 B9 B4 A6 A3 B1 B0 A0 A1 A7 B2]
time 48890ms: Process B7 completed I/O; added to ready queue [Q A9 B9 B4 A6 A3 B1 B0 A0 A1 A7 B2 B7]
time 48941ms: Process A2 completed I/O; added to ready queue [Q A9 B9 B4 A6 A3 B1 B0 A0 A1 A7 B2 B7 A2]
time 49002ms: Process B5 completed a CPU burst; 21 bursts to go [Q A9 B9 B4 A6 A3 B1 B0 A0 A1 A7 B2 B7 A2]
time 49002ms: Process B5 switching out of CPU; blocking on I/O until time 49044ms [Q A9 B9 B4 A6 A3 B1 B0 A0 A1 A7 B2 B7 A2]
time 49006ms: Process A9 started using the CPU for 464ms burst [Q B9 B4 A6 A3 B1 B0 A0 A1 A7 B2 B7 A2]
time 49044ms: Process B5 completed I/O; added to ready queue [Q B9 B4 A6 A3 B1 B0 A0 A1 A7 B2 B7 A2 B5]
time 49230ms: Process B8 completed I/O; added to ready queue [Q B9 B4 A6 A3 B1 B0 A0 A1 A7 B2 B7 A2 B5 B8]
time 49470ms: Process A9 completed a CPU burst; 22 bursts to go [Q B9 B4 A6 A3 B1 B0 A0 A1 A7 B2 B7 A2 B5 B8]
time 49470ms: Process A9 switching out of CPU; blocking on I/O until time 49476ms [Q B9 B4 A6 A3 B1 B0 A0 A1 A7 B2 B7 A2 B5 B8]
time 49474ms: Process B9 started using the CPU for 77ms burst [Q B4 A6 A3 B1 B0 A0 A1 A7 B2 B7 A2 B5 B8]
time 49476ms: Process A9 completed I/O; added to ready queue [Q B4 A6 A3 B1 B0 A0 A1 A7 B2 B7 A2 B5 B8 A9]
time 49551ms: Process B9 completed a CPU burst; 2 bursts to go [Q B4 A6 A3 B1 B0 A0 A1 A7 B2 B7 A2 B5 B8 A9]
time 49551ms: Process B9 switching out of CPU; blocking on I/O until time 50897ms [Q B4 A6 A3 B1 B0 A0 A1 A7 B2 B7 A2 B5 B8 A9]
time 49555ms: Process B4 started using the CPU for 44ms burst [Q A6 A3 B1 B0 A0 A1 A7 B2 B7 A2 B5 B8 A9]
time 49599ms: Process B4 completed a CPU burst; 7 bursts to go [Q A6 A3 B1 B0 A0 A1 A7 B2 B7 A2 B5 B8 A9]
time 49599ms: Process B4 switching out of CPU; blocking on I/O until time 50945ms [Q A6 A3 B1 B0 A0 A1 A7 B2 B7 A2 B5 B8 A9]
time 49603ms: Process A6 started using the CPU for 132ms burst [Q A3 B1 B0 A0 A1 A7 B2 B7 A2 B5 B8 A9]
time 49735ms: Process A6 completed a CPU burst; 8 bursts to go [Q A3 B1 B0 A0 A1 A7 B2 B7 A2 B5 B8 A9]
time 49735ms: Process A6 switching out of CPU; blocking on I/O until time 49749ms [Q A3 B1 B0 A0 A1 A7 B2 B7 A2 B5 B8 A9]
time 49739ms: Process A3 started using the CPU for 440ms burst [Q B1 B0 A0 A1 A7 B2 B7 A2 B5 B8 A9]
time 49749ms: Process A6 completed I/O; added to ready queue [Q B1 B0 A0 A1 A7 B2 B7 A2 B5 B8 A9 A6]
time 50179ms: Process A3 completed a CPU burst; 17 bursts to go [Q B1 B0 A0 A1 A7 B2 B7 A2 B5 B8 A9 A6]
time 50179ms: Process A3 switching out of CPU; blocking on I/O until time 50240ms [Q B1 B0 A0 A1 A7 B2 B7 A2 B5 B8 A9 A6]
time 50183ms: Process B1 started using the CPU for 76ms burst [Q B0 A0 A1 A7 B2 B7 A2 B5 B8 A9 A6]
time 50240ms: Process A3 completed I/O; added to ready queue [Q B0 A0 A1 A7 B2 B7 A2 B5 B8 A9 A6 A3]
time 50259ms: Process B1 completed a CPU burst; 7 bursts to go [Q B0 A0 A1 A7 B2 B7 A2 B5 B8 A9 A6 A3]
time 50259ms: Process B1 switching out of CPU; blocking on I/O until time 50299ms [Q B0 A0 A1 A7 B2 B7 A2 B5 B8 A9 A6 A3]
time 50263ms: Process B0 started using the CPU for 336ms burst [Q A0 A1 A7 B2 B7 A2 B5 B8 A9 A6 A3]
time 50299ms: Process B1 completed I/O; added to ready queue [Q A0 A1 A7 B2 B7 A2 B5 B8 A9 A6 A3 B1]
time 50599ms: Process B0 completed a CPU burst; 9 bursts to go [Q A0 A1 A7 B2 B7 A2 B5 B8 A9 A6 A3 B1]
time 50599ms: Process B0 switching out of CPU; blocking on I/O until time 50662ms [Q A0 A1 A7 B2 B7 A2 B5 B8 A9 A6 A3 B1]
time 50603ms: Process A0 started using the CPU for 124ms burst [Q A1 A7 B2 B7 A2 B5 B8 A9 A6 A3 B1]
time 50662ms: Process B0 completed I/O; added to ready queue [Q A1 A7 B2 B7 A2 B5 B8 A9 A6 A3 B1 B0]
time 50675ms: Process B3 completed I/O; added to ready queue [Q A1 A7 B2 B7 A2 B5 B8 A9 A6 A3 B1 B0 B3]
time 50727ms: Process A0 completed a CPU burst; 20 bursts to go [Q A1 A7 B2 B7 A2 B5 B8 A9 A6 A3 B1 B0 B3]
time 50727ms: Process A0 switching out of CPU; blocking on I/O until time 51077ms [Q A1 A7 B2 B7 A2 B5 B8 A9 A6 A3 B1 B0 B3]
time 50731ms: Process A1 started using the CPU for 584ms burst [Q A7 B2 B7 A2 B5 B8 A9 A6 A3 B1 B0 B3]
time 50897ms: Process B9 completed I/O; added to ready queue [Q A7 B2 B7 A2 B5 B8 A9 A6 A3 B1 B0 B3 B9]
time 50945ms: Process B4 completed I/O; added to ready queue [Q A7 B2 B7 A2 B5 B8 A9 A6 A3 B1 B0 B3 B9 B4]
time 51077ms: Process A0 completed I/O; added to ready queue [Q A7 B2 B7 A2 B5 B8 A9 A6 A3 B1 B0 B3 B9 B4 A0]
time 51315ms: Process A1 completed a CPU burst; 2 bursts to go [Q A7 B2 B7 A2 B5 B8 A9 A6 A3 B1 B0 B3 B9 B4 A0]
time 51315ms: Process A1 switching out of CPU; blocking on I/O until time 51548ms [Q A7 B2 B7 A2 B5 B8 A9 A6 A3 B1 B0 B3 B9 B4 A0]
time 51319ms: Process A7 started using the CPU for 24ms burst [Q B2 B7 A2 B5 B8 A9 A6 A3 B1 B0 B3 B9 B4 A0]
time 51343ms: Process A7 completed a CPU burst; 9 bursts to go [Q B2 B7 A2 B5 B8 A9 A6 A3 B1 B0 B3 B9 B4 A0]
time 51343ms: Process A7 switching out of CPU; blocking on I/O until time 51596ms [Q B2 B7 A2 B5 B8 A9 A6 A3 B1 B0 B3 B9 B4 A0]
time 51347ms: Process B2 started using the CPU for 103ms burst [Q B7 A2 B5 B8 A9 A6 A3 B1 B0 B3 B9 B4 A0]
time 51450ms: Process B2 completed a CPU burst; 5 bursts to go [Q B7 A2 B5 B8 A9 A6 A3 B1 B0 B3 B9 B4 A0]
time 51450ms: Process B2 switching out of CPU; blocking on I/O until time 51540ms [Q B7 A2 B5 B8 A9 A6 A3 B1 B0 B3 B9 B4 A0]
time 51454ms: Process B7 started using the CPU for 140ms burst [Q A2 B5 B8 A9 A6 A3 B1 B0 B3 B9 B4 A0]
time 51540ms: Process B2 completed I/O; added to ready queue [Q A2 B5 B8 A9 A6 A3 B1 B0 B3 B9 B4 A0 B2]
time 51548ms: Process A1 completed I/O; added to ready queue [Q A2 B5 B8 A9 A6 A3 B1 B0 B3 B9 B4 A0 B2 A1]
time 51594ms: Process B7 completed a CPU burst; 18 bursts to go [Q A2 B5 B8 A9 A6 A3 B1 B0 B3 B9 B4 A0 B2 A1]
time 51594ms: Process B7 switching out of CPU; blocking on I/O until time 52252ms [Q A2 B5 B8 A9 A6 A3 B1 B0 B3 B9 B4 A0 B2 A1]
time 51596ms: Process A7 completed I/O; added to ready queue [Q A2 B5 B8 A9 A6 A3 B1 B0 B3 B9 B4 A0 B2 A1 A7]
time 51598ms: Process A2 started using the CPU for 460ms burst [Q B5 B8 A9 A6 A3 B1 B0 B3 B9 B4 A0 B2 A1 A7]
time 52058ms: Process A2 completed a CPU burst; 20 bursts to go [Q B5 B8 A9 A6 A3 B1 B0 B3 B9 B4 A0 B2 A1 A7]
time 52058ms: Process A2 switching out of CPU; blocking on I/O until time 52316ms [Q B5 B8 A9 A6 A3 B1 B0 B3 B9 B4 A0 B2 A1 A7]
time 52062ms: Process B5 started using the CPU for 14ms burst [Q B8 A9 A6 A3 B1 B0 B3 B9 B4 A0 B2 A1 A7]
time 52076ms: Process B5 completed a CPU burst; 20 bursts to go [Q B8 A9 A6 A3 B1 B0 B3 B9 B4 A0 B2 A1 A7]
time 52076ms: Process B5 switching out of CPU; blocking on I/O until time 52598ms [Q B8 A9 A6 A3 B1 B0 B3 B9 B4 A0 B2 A1 A7]
time 52080ms: Process B8 started using the CPU for 33ms burst [Q A9 A6 A3 B1 B0 B3 B9 B4 A0 B2 A1 A7]
time 52113ms: Process B8 completed a CPU burst; 11 bursts to go [Q A9 A6 A3 B1 B0 B3 B9 B4 A0 B2 A1 A7]
time 52113ms: Process B8 switching out of CPU; blocking on I/O until time 52483ms [Q A9 A6 A3 B1 B0 B3 B9 B4 A0 B2 A1 A7]
time 52117ms: Process A9 started using the CPU for 712ms burst [Q A6 A3 B1 B0 B3 B9 B4 A0 B2 A1 A7]
time 52252ms: Process B7 completed I/O; added to ready queue [Q A6 A3 B1 B0 B3 B9 B4 A0 B2 A1 A7 B7]
time 52316ms: Process A2 completed I/O; added to ready queue [Q A6 A3 B1 B0 B3 B9 B4 A0 B2 A1 A7 B7 A2]
time 52483ms: Process B8 completed I/O; added to ready queue [Q A6 A3 B1 B0 B3 B9 B4 A0 B2 A1 A7 B7 A2 B8]
time 52598ms: Process B5 completed I/O; added to ready queue [Q A6 A3 B1 B0 B3 B9 B4 A0 B2 A1 A7 B7 A2 B8 B5]
time 52829ms: Process A9 completed a CPU burst; 21 bursts to go [Q A6 A3 B1 B0 B3 B9 B4 A0 B2 A1 A7 B7 A2 B8 B5]
time 52829ms: Process A9 switching out of CPU; blocking on I/O until time 52880ms [Q A6 A3 B1 B0 B3 B9 B4 A0 B2 A1 A7 B7 A2 B8 B5]
time 52833ms: Process A6 started using the CPU for 780ms burst [Q A3 B1 B0 B3 B9 B4 A0 B2 A1 A7 B7 A2 B8 B5]
time 52880ms: Process A9 completed I/O; added to ready queue [Q A3 B1 B0 B3 B9 B4 A0 B2 A1 A7 B7 A2 B8 B5 A9]
time 53613ms: Process A6 completed a CPU burst; 7 bursts to go [Q A3 B1 B0 B3 B9 B4 A0 B2 A1 A7 B7 A2 B8 B5 A9]
time 53613ms: Process A6 switching out of CPU; blocking on I/O until time 53635ms [Q A3 B1 B0 B3 B9 B4 A0 B2 A1 A7 B7 A2 B8 B5 A9]
time 53617ms: Process A3 started using the CPU for 252ms burst [Q B1 B0 B3 B9 B4 A0 B2 A1 A7 B7 A2 B8 B5 A9]
time 53635ms: Process A6 completed I/O; added to ready queue [Q B1 B0 B3 B9 B4 A0 B2 A1 A7 B7 A2 B8 B5 A9 A6]
time 53869ms: Process A3 completed a CPU burst; 16 bursts to go [Q B1 B0 B3 B9 B4 A0 B2 A1 A7 B7 A2 B8 B5 A9 A6]
time 53869ms: Process A3 switching out of CPU; blocking on I/O until time 54073ms [Q B1 B0 B3 B9 B4 A0 B2 A1 A7 B7 A2 B8 B5 A9 A6]
time 53873ms: Process B1 started using the CPU for 112ms burst [Q B0 B3 B9 B4 A0 B2 A1 A7 B7 A2 B8 B5 A9 A6]
time 53985ms: Process B1 completed a CPU burst; 6 bursts to go [Q B0 B3 B9 B4 A0 B2 A1 A7 B7 A2 B8 B5 A9 A6]
time 53985ms: Process B1 switching out of CPU; blocking on I/O until time 54114ms [Q B0 B3 B9 B4 A0 B2 A1 A7 B7 A2 B8 B5 A9 A6]
time 53989ms: Process B0 started using the CPU for 432ms burst [Q B3 B9 B4 A0 B2 A1 A7 B7 A2 B8 B5 A9 A6]
time 54073ms: Process A3 completed I/O; added to ready queue [Q B3 B9 B4 A0 B2 A1 A7 B7 A2 B8 B5 A9 A6 A3]
time 54114ms: Process B1 completed I/O; added to ready queue [Q B3 B9 B4 A0 B2 A1 A7 B7 A2 B8 B5 A9 A6 A3 B1]
time 54421ms: Process B0 completed a CPU burst; 8 bursts to go [Q B3 B9 B4 A0 B2 A1 A7 B7 A2 B8 B5 A9 A6 A3 B1]
time 54421ms: Process B0 switching out of CPU; blocking on I/O until time 54450ms [Q B3 B9 B4 A0 B2 A1 A7 B7 A2 B8 B5 A9 A6 A3 B1]
time 54425ms: Process B3 started using the CPU for 10ms burst [Q B9 B4 A0 B2 A1 A7 B7 A2 B8 B5 A9 A6 A3 B1]
time 54435ms: Process B3 completed a CPU burst; 14 bursts to go [Q B9 B4 A0 B2 A1 A7 B7 A2 B8 B5 A9 A6 A3 B1]
time 54435ms: Process B3 switching out of CPU; blocking on I/O until time 55173ms [Q B9 B4 A0 B2 A1 A7 B7 A2 B8 B5 A9 A6 A3 B1]
time 54439ms: Process B9 started using the CPU for 35ms burst [Q B4 A0 B2 A1 A7 B7 A2 B8 B5 A9 A6 A3 B1]
time 54450ms: Process B0 completed I/O; added to ready queue [Q B4 A0 B2 A1 A7 B7 A2 B8 B5 A9 A6 A3 B1 B0]
time 54474ms: Process B9 completed a CPU burst; 1 burst to go [Q B4 A0 B2 A1 A7 B7 A2 B8 B5 A9 A6 A3 B1 B0]
time 54474ms: Process B9 switching out of CPU; blocking on I/O until time 55260ms [Q B4 A0 B2 A1 A7 B7 A2 B8 B5 A9 A6 A3 B1 B0]
time 54478ms: Process B4 started using the CPU for 26ms burst [Q A0 B2 A1 A7 B7 A2 B8 B5 A9 A6 A3 B1 B0]
time 54504ms: Process B4 completed a CPU burst; 6 bursts to go [Q A0 B2 A1 A7 B7 A2 B8 B5 A9 A6 A3 B1 B0]
time 54504ms: Process B4 switching out of CPU; blocking on I/O until time 54562ms [Q A0 B2 A1 A7 B7 A2 B8 B5 A9 A6 A3 B1 B0]
time 54508ms: Process A0 started using the CPU for 208ms burst [Q B2 A1 A7 B7 A2 B8 B5 A9 A6 A3 B1 B0]
time 54562ms: Process B4 completed I/O; added to ready queue [Q B2 A1 A7 B7 A2 B8 B5 A9 A6 A3 B1 B0 B4]
time 54716ms: Process A0 completed a CPU burst; 19 bursts to go [Q B2 A1 A7 B7 A2 B8 B5 A9 A6 A3 B1 B0 B4]
time 54716ms: Process A0 switching out of CPU; blocking on I/O until time 54745ms [Q B2 A1 A7 B7 A2 B8 B5 A9 A6 A3 B1 B0 B4]
time 54720ms: Process B2 started using the CPU for 31ms burst [Q A1 A7 B7 A2 B8 B5 A9 A6 A3 B1 B0 B4]
time 54745ms: Process A0 completed I/O; added to ready queue [Q A1 A7 B7 A2 B8 B5 A9 A6 A3 B1 B0 B4 A0]
time 54751ms: Process B2 completed a CPU burst; 4 bursts to go [Q A1 A7 B7 A2 B8 B5 A9 A6 A3 B1 B0 B4 A0]
time 54751ms: Process B2 switching out of CPU; blocking on I/O until time 55649ms [Q A1 A7 B7 A2 B8 B5 A9 A6 A3 B1 B0 B4 A0]
time 54755ms: Process A1 started using the CPU for 1032ms burst [Q A7 B7 A2 B8 B5 A9 A6 A3 B1 B0 B4 A0]
time 55173ms: Process B3 completed I/O; added to ready queue [Q A7 B7 A2 B8 B5 A9 A6 A3 B1 B0 B4 A0 B3]
time 55260ms: Process B9 completed I/O; added to ready queue [Q A7 B7 A2 B8 B5 A9 A6 A3 B1 B0 B4 A0 B3 B9]
time 55649ms: Process B2 completed I/O; added to ready queue [Q A7 B7 A2 B8 B5 A9 A6 A3 B1 B0 B4 A0 B3 B9 B2]
time 55787ms: Process A1 completed a CPU burst; 1 burst to go [Q A7 B7 A2 B8 B5 A9 A6 A3 B1 B0 B4 A0 B3 B9 B2]
time 55787ms: Process A1 switching out of CPU; blocking on I/O until time 55883ms [Q A7 B7 A2 B8 B5 A9 A6 A3 B1 B0 B4 A0 B3 B9 B2]
time 55791ms: Process A7 started using the CPU for 376ms burst [Q B7 A2 B8 B5 A9 A6 A3 B1 B0 B4 A0 B3 B9 B2]
time 55883ms: Process A1 completed I/O; added to ready queue [Q B7 A2 B8 B5 A9 A6 A3 B1 B0 B4 A0 B3 B9 B2 A1]
time 56167ms: Process A7 completed a CPU burst; 8 bursts to go [Q B7 A2 B8 B5 A9 A6 A3 B1 B0 B4 A0 B3 B9 B2 A1]
time 56167ms: Process A7 switching out of CPU; blocking on I/O until time 56171ms [Q B7 A2 B8 B5 A9 A6 A3 B1 B0 B4 A0 B3 B9 B2 A1]
time 56171ms: Process B7 started using the CPU for 317ms burst [Q A2 B8 B5 A9 A6 A3 B1 B0 B4 A0 B3 B9 B2 A1]
time 56171ms: Process A7 completed I/O; added to ready queue [Q A2 B8 B5 A9 A6 A3 B1 B0 B4 A0 B3 B9 B2 A1 A7]
time 56488ms: Process B7 completed a CPU burst; 17 bursts to go [Q A2 B8 B5 A9 A6 A3 B1 B0 B4 A0 B3 B9 B2 A1 A7]
time 56488ms: Process B7 switching out of CPU; blocking on I/O until time 56538ms [Q A2 B8 B5 A9 A6 A3 B1 B0 B4 A0 B3 B9 B2 A1 A7]
time 56492ms: Process A2 started using the CPU for 256ms burst [Q B8 B5 A9 A6 A3 B1 B0 B4 A0 B3 B9 B2 A1 A7]
time 56538ms: Process B7 completed I/O; added to ready queue [Q B8 B5 A9 A6 A3 B1 B0 B4 A0 B3 B9 B2 A1 A7 B7]
time 56748ms: Process A2 completed a CPU burst; 19 bursts to go [Q B8 B5 A9 A6 A3 B1 B0 B4 A0 B3 B9 B2 A1 A7 B7]
time 56748ms: Process A2 switching out of CPU; blocking on I/O until time 56774ms [Q B8 B5 A9 A6 A3 B1 B0 B4 A0 B3 B9 B2 A1 A7 B7]
time 56752ms: Process B8 started using the CPU for 66ms burst [Q B5 A9 A6 A3 B1 B0 B4 A0 B3 B9 B2 A1 A7 B7]
time 56774ms: Process A2 completed I/O; added to ready queue [Q B5 A9 A6 A3 B1 B0 B4 A0 B3 B9 B2 A1 A7 B7 A2]
time 56818ms: Process B8 completed a CPU burst; 10 bursts to go [Q B5 A9 A6 A3 B1 B0 B4 A0 B3 B9 B2 A1 A7 B7 A2]
time 56818ms: Process B8 switching out of CPU; blocking on I/O until time 58092ms [Q B5 A9 A6 A3 B1 B0 B4 A0 B3 B9 B2 A1 A7 B7 A2]
time 56822ms: Process B5 started using the CPU for 174ms burst [Q A9 A6 A3 B1 B0 B4 A0 B3 B9 B2 A1 A7 B7 A2]
time 56996ms: Process B5 completed a CPU burst; 19 bursts to go [Q A9 A6 A3 B1 B0 B4 A0 B3 B9 B2 A1 A7 B7 A2]
time 56996ms: Process B5 switching out of CPU; blocking on I/O until time 58014ms [Q A9 A6 A3 B1 B0 B4 A0 B3 B9 B2 A1 A7 B7 A2]
time 57000ms: Process A9 started using the CPU for 1680ms burst [Q A6 A3 B1 B0 B4 A0 B3 B9 B2 A1 A7 B7 A2]
time 58014ms: Process B5 completed I/O; added to ready queue [Q A6 A3 B1 B0 B4 A0 B3 B9 B2 A1 A7 B7 A2 B5]
time 58092ms: Process B8 completed I/O; added to ready queue [Q A6 A3 B1 B0 B4 A0 B3 B9 B2 A1 A7 B7 A2 B5 B8]
time 58680ms: Process A9 completed a CPU burst; 20 bursts to go [Q A6 A3 B1 B0 B4 A0 B3 B9 B2 A1 A7 B7 A2 B5 B8]
time 58680ms: Process A9 switching out of CPU; blocking on I/O until time 58714ms [Q A6 A3 B1 B0 B4 A0 B3 B9 B2 A1 A7 B7 A2 B5 B8]
time 58684ms: Process A6 started using the CPU for 308ms burst [Q A3 B1 B0 B4 A0 B3 B9 B2 A1 A7 B7 A2 B5 B8]
time 58714ms: Process A9 completed I/O; added to ready queue [Q A3 B1 B0 B4 A0 B3 B9 B2 A1 A7 B7 A2 B5 B8 A9]
time 58992ms: Process A6 completed a CPU burst; 6 bursts to go [Q A3 B1 B0 B4 A0 B3 B9 B2 A1 A7 B7 A2 B5 B8 A9]
time 58992ms: Process A6 switching out of CPU; blocking on I/O until time 59038ms [Q A3 B1 B0 B4 A0 B3 B9 B2 A1 A7 B7 A2 B5 B8 A9]
time 58996ms: Process A3 started using the CPU for 300ms burst [Q B1 B0 B4 A0 B3 B9 B2 A1 A7 B7 A2 B5 B8 A9]
time 59038ms: Process A6 completed I/O; added to ready queue [Q B1 B0 B4 A0 B3 B9 B2 A1 A7 B7 A2 B5 B8 A9 A6]
time 59296ms: Process A3 completed a CPU burst; 15 bursts to go [Q B1 B0 B4 A0 B3 B9 B2 A1 A7 B7 A2 B5 B8 A9 A6]
time 59296ms: Process A3 switching out of CPU; blocking on I/O until time 59394ms [Q B1 B0 B4 A0 B3 B9 B2 A1 A7 B7 A2 B5 B8 A9 A6]
time 59300ms: Process B1 started using the CPU for 392ms burst [Q B0 B4 A0 B3 B9 B2 A1 A7 B7 A2 B5 B8 A9 A6]
time 59394ms: Process A3 completed I/O; added to ready queue [Q B0 B4 A0 B3 B9 B2 A1 A7 B7 A2 B5 B8 A9 A6 A3]
time 59692ms: Process B1 completed a CPU burst; 5 bursts to go [Q B0 B4 A0 B3 B9 B2 A1 A7 B7 A2 B5 B8 A9 A6 A3]
time 59692ms: Process B1 switching out of CPU; blocking on I/O until time 59935ms [Q B0 B4 A0 B3 B9 B2 A1 A7 B7 A2 B5 B8 A9 A6 A3]
time 59696ms: Process B0 started using the CPU for 180ms burst [Q B4 A0 B3 B9 B2 A1 A7 B7 A2 B5 B8 A9 A6 A3]
time 59876ms: Process B0 completed a CPU burst; 7 bursts to go [Q B4 A0 B3 B9 B2 A1 A7 B7 A2 B5 B8 A9 A6 A3]
time 59876ms: Process B0 switching out of CPU; blocking on I/O until time 59909ms [Q B4 A0 B3 B9 B2 A1 A7 B7 A2 B5 B8 A9 A6 A3]
time 59880ms: Process B4 started using the CPU for 8ms burst [Q A0 B3 B9 B2 A1 A7 B7 A2 B5 B8 A9 A6 A3]
time 59888ms: Process B4 completed a CPU burst; 5 bursts to go [Q A0 B3 B9 B2 A1 A7 B7 A2 B5 B8 A9 A6 A3]
time 59888ms: Process B4 switching out of CPU; blocking on I/O until time 61682ms [Q A0 B3 B9 B2 A1 A7 B7 A2 B5 B8 A9 A6 A3]
time 59892ms: Process A0 started using the CPU for 708ms burst [Q B3 B9 B2 A1 A7 B7 A2 B5 B8 A9 A6 A3]
time 59909ms: Process B0 completed I/O; added to ready queue [Q B3 B9 B2 A1 A7 B7 A2 B5 B8 A9 A6 A3 B0]
time 59935ms: Process B1 completed I/O; added to ready queue [Q B3 B9 B2 A1 A7 B7 A2 B5 B8 A9 A6 A3 B0 B1]
time 60600ms: Process A0 completed a CPU burst; 18 bursts to go [Q B3 B9 B2 A1 A7 B7 A2 B5 B8 A9 A6 A3 B0 B1]
time 60600ms: Process A0 switching out of CPU; blocking on I/O until time 60630ms [Q B3 B9 B2 A1 A7 B7 A2 B5 B8 A9 A6 A3 B0 B1]
time 60604ms: Process B3 started using the CPU for 89ms burst [Q B9 B2 A1 A7 B7 A2 B5 B8 A9 A6 A3 B0 B1]
time 60630ms: Process A0 completed I/O; added to ready queue [Q B9 B2 A1 A7 B7 A2 B5 B8 A9 A6 A3 B0 B1 A0]
time 60693ms: Process B3 completed a CPU burst; 13 bursts to go [Q B9 B2 A1 A7 B7 A2 B5 B8 A9 A6 A3 B0 B1 A0]
time 60693ms: Process B3 switching out of CPU; blocking on I/O until time 61143ms [Q B9 B2 A1 A7 B7 A2 B5 B8 A9 A6 A3 B0 B1 A0]
time 60697ms: Process B9 started using the CPU for 19ms burst [Q B2 A1 A7 B7 A2 B5 B8 A9 A6 A3 B0 B1 A0]
time 60716ms: Process B9 terminated [Q B2 A1 A7 B7 A2 B5 B8 A9 A6 A3 B0 B1 A0]
time 60720ms: Process B2 started using the CPU for 170ms burst [Q A1 A7 B7 A2 B5 B8 A9 A6 A3 B0 B1 A0]
time 60890ms: Process B2 completed a CPU burst; 3 bursts to go [Q A1 A7 B7 A2 B5 B8 A9 A6 A3 B0 B1 A0]
time 60890ms: Process B2 switching out of CPU; blocking on I/O until time 62148ms [Q A1 A7 B7 A2 B5 B8 A9 A6 A3 B0 B1 A0]
time 60894ms: Process A1 started using the CPU for 188ms burst [Q A7 B7 A2 B5 B8 A9 A6 A3 B0 B1 A0]
time 61082ms: Process A1 terminated [Q A7 B7 A2 B5 B8 A9 A6 A3 B0 B1 A0]
time 61086ms: Process A7 started using the CPU for 8ms burst [Q B7 A2 B5 B8 A9 A6 A3 B0 B1 A0]
time 61094ms: Process A7 completed a CPU burst; 7 bursts to go [Q B7 A2 B5 B8 A9 A6 A3 B0 B1 A0]
time 61094ms: Process A7 switching out of CPU; blocking on I/O until time 61261ms [Q B7 A2 B5 B8 A9 A6 A3 B0 B1 A0]
time 61098ms: Process B7 started using the CPU for 104ms burst [Q A2 B5 B8 A9 A6 A3 B0 B1 A0]
time 61143ms: Process B3 completed I/O; added to ready queue [Q A2 B5 B8 A9 A6 A3 B0 B1 A0 B3]
time 61202ms: Process B7 completed a CPU burst; 16 bursts to go [Q A2 B5 B8 A9 A6 A3 B0 B1 A0 B3]
time 61202ms: Process B7 switching out of CPU; blocking on I/O until time 62116ms [Q A2 B5 B8 A9 A6 A3 B0 B1 A0 B3]
time 61206ms: Process A2 started using the CPU for 280ms burst [Q B5 B8 A9 A6 A3 B0 B1 A0 B3]
time 61261ms: Process A7 completed I/O; added to ready queue [Q B5 B8 A9 A6 A3 B0 B1 A0 B3 A7]
time 61486ms: Process A2 completed a CPU burst; 18 bursts to go [Q B5 B8 A9 A6 A3 B0 B1 A0 B3 A7]
time 61486ms: Process A2 switching out of CPU; blocking on I/O until time 61660ms [Q B5 B8 A9 A6 A3 B0 B1 A0 B3 A7]
time 61490ms: Process B5 started using the CPU for 33ms burst [Q B8 A9 A6 A3 B0 B1 A0 B3 A7]
time 61523ms: Process B5 completed a CPU burst; 18 bursts to go [Q B8 A9 A6 A3 B0 B1 A0 B3 A7]
time 61523ms: Process B5 switching out of CPU; blocking on I/O until time 63341ms [Q B8 A9 A6 A3 B0 B1 A0 B3 A7]
time 61527ms: Process B8 started using the CPU for 23ms burst [Q A9 A6 A3 B0 B1 A0 B3 A7]
time 61550ms: Process B8 completed a CPU burst; 9 bursts to go [Q A9 A6 A3 B0 B1 A0 B3 A7]
time 61550ms: Process B8 switching out of CPU; blocking on I/O until time 61600ms [Q A9 A6 A3 B0 B1 A0 B3 A7]
time 61554ms: Process A9 started using the CPU for 140ms burst [Q A6 A3 B0 B1 A0 B3 A7]
time 61600ms: Process B8 completed I/O; added to ready queue [Q A6 A3 B0 B1 A0 B3 A7 B8]
time 61660ms: Process A2 completed I/O; added to ready queue [Q A6 A3 B0 B1 A0 B3 A7 B8 A2]
time 61682ms: Process B4 completed I/O; added to ready queue [Q A6 A3 B0 B1 A0 B3 A7 B8 A2 B4]
time 61694ms: Process A9 completed a CPU burst; 19 bursts to go [Q A6 A3 B0 B1 A0 B3 A7 B8 A2 B4]
time 61694ms: Process A9 switching out of CPU; blocking on I/O until time 61978ms [Q A6 A3 B0 B1 A0 B3 A7 B8 A2 B4]
time 61698ms: Process A6 started using the CPU for 184ms burst [Q A3 B0 B1 A0 B3 A7 B8 A2 B4]
time 61882ms: Process A6 completed a CPU burst; 5 bursts to go [Q A3 B0 B1 A0 B3 A7 B8 A2 B4]
time 61882ms: Process A6 switching out of CPU; blocking on I/O until time 62004ms [Q A3 B0 B1 A0 B3 A7 B8 A2 B4]
time 61886ms: Process A3 started using the CPU for 268ms burst [Q B0 B1 A0 B3 A7 B8 A2 B4]
time 61978ms: Process A9 completed I/O; added to ready queue [Q B0 B1 A0 B3 A7 B8 A2 B4 A9]
time 62004ms: Process A6 completed I/O; added to ready queue [Q B0 B1 A0 B3 A7 B8 A2 B4 A9 A6]
time 62116ms: Process B7 completed I/O; added to ready queue [Q B0 B1 A0 B3 A7 B8 A2 B4 A9 A6 B7]
time 62148ms: Process B2 completed I/O; added to ready queue [Q B0 B1 A0 B3 A7 B8 A2 B4 A9 A6 B7 B2]
time 62154ms: Process A3 completed a CPU burst; 14 bursts to go [Q B0 B1 A0 B3 A7 B8 A2 B4 A9 A6 B7 B2]
time 62154ms: Process A3 switching out of CPU; blocking on I/O until time 62425ms [Q B0 B1 A0 B3 A7 B8 A2 B4 A9 A6 B7 B2]
time 62158ms: Process B0 started using the CPU for 28ms burst [Q B1 A0 B3 A7 B8 A2 B4 A9 A6 B7 B2]
time 62186ms: Process B0 completed a CPU burst; 6 bursts to go [Q B1 A0 B3 A7 B8 A2 B4 A9 A6 B7 B2]
time 62186ms: Process B0 switching out of CPU; blocking on I/O until time 62290ms [Q B1 A0 B3 A7 B8 A2 B4 A9 A6 B7 B2]
time 62190ms: Process B1 started using the CPU for 256ms burst [Q A0 B3 A7 B8 A2 B4 A9 A6 B7 B2]
time 62290ms: Process B0 completed I/O; added to ready queue [Q A0 B3 A7 B8 A2 B4 A9 A6 B7 B2 B0]
time 62425ms: Process A3 completed I/O; added to ready queue [Q A0 B3 A7 B8 A2 B4 A9 A6 B7 B2 B0 A3]
time 62446ms: Process B1 completed a CPU burst; 4 bursts to go [Q A0 B3 A7 B8 A2 B4 A9 A6 B7 B2 B0 A3]
time 62446ms: Process B1 switching out of CPU; blocking on I/O until time 62631ms [Q A0 B3 A7 B8 A2 B4 A9 A6 B7 B2 B0 A3]
time 62450ms: Process A0 started using the CPU for 64ms burst [Q B3 A7 B8 A2 B4 A9 A6 B7 B2 B0 A3]
time 62514ms: Process A0 completed a CPU burst; 17 bursts to go [Q B3 A7 B8 A2 B4 A9 A6 B7 B2 B0 A3]
time 62514ms: Process A0 switching out of CPU; blocking on I/O until time 62640ms [Q B3 A7 B8 A2 B4 A9 A6 B7 B2 B0 A3]
time 62518ms: Process B3 started using the CPU for 5ms burst [Q A7 B8 A2 B4 A9 A6 B7 B2 B0 A3]
time 62523ms: Process B3 completed a CPU burst; 12 bursts to go [Q A7 B8 A2 B4 A9 A6 B7 B2 B0 A3]
time 62523ms: Process B3 switching out of CPU; blocking on I/O until time 64269ms [Q A7 B8 A2 B4 A9 A6 B7 B2 B0 A3]
time 62527ms: Process A7 started using the CPU for 248ms burst [Q B8 A2 B4 A9 A6 B7 B2 B0 A3]
time 62631ms: Process B1 completed I/O; added to ready queue [Q B8 A2 B4 A9 A6 B7 B2 B0 A3 B1]
time 62640ms: Process A0 completed I/O; added to ready queue [Q B8 A2 B4 A9 A6 B7 B2 B0 A3 B1 A0]
time 62775ms: Process A7 completed a CPU burst; 6 bursts to go [Q B8 A2 B4 A9 A6 B7 B2 B0 A3 B1 A0]
